Workbook

Sheet TTD-DOS
A1: Num | B1: R | C1: G | D1: B | E1: Min | F1: Colour | G1: Name | H1: {=INDEX('Ral Classic'!$A:$A,COLUMN()-COLUMN($H$1)+2,1)} -> RAL 1000 | I1: {=INDEX('Ral Classic'!$A:$A,COLUMN()-COLUMN($H$1)+2,1)} -> RAL 1001 | J1: {=INDEX('Ral Classic'!$A:$A,COLUMN()-COLUMN($H$1)+2,1)} -> RAL 1002 | K1: {=INDEX('Ral Classic'!$A:$A,COLUMN()-COLUMN($H$1)+2,1)} -> RAL 1003 | L1: {=INDEX('Ral Classic'!$A:$A,COLUMN()-COLUMN($H$1)+2,1)} -> RAL 1004 | M1: {=INDEX('Ral Classic'!$A:$A,COLUMN()-COLUMN($H$1)+2,1)} -> RAL 1005 | N1: {=INDEX('Ral Classic'!$A:$A,COLUMN()-COLUMN($H$1)+2,1)} -> RAL 1006 | O1: {=INDEX('Ral Classic'!$A:$A,COLUMN()-COLUMN($H$1)+2,1)} -> RAL 1007 | ... HL1: {=INDEX('Ral Classic'!$A:$A,COLUMN()-COLUMN($H$1)+2,1)} -> RAL 9023
A2: 0 | B2: 0 | C2: 0 | D2: 255 | E2: =MIN(H2:HL2) -> 144.77914 | F2: {=INDEX($1:$1,1,CELL("столбец",INDEX(H2:HL2,MATCH(MIN(H2:HL2),H2:HL2,0))))} -> RAL 5005 | G2: =VLOOKUP(F2,'Ral Classic'!$A:$N,COLUMN('Ral Classic'!$L$1),FALSE) -> Signal blue | H2: =POWER(POWER(VLOOKUP(H$1,'Ral Classic'!$A:$D,COLUMN('Ral Classic'!$B1),FALSE)-$B2,2)+POWER(VLOOKUP(H$1,'Ral Classic'!$A:$D,COLUMN('Ral Classic'!$C1),FALSE)-$C2,2)+POWER(VLOOKUP(H$1,'Ral Classic'!$A:$D,COLUMN('Ral Classic'!$D1),FALSE)-$D2,2),1/2) -> 301.30051 | I2: =POWER(POWER(VLOOKUP(I$1,'Ral Classic'!$A:$D,COLUMN('Ral Classic'!$B1),FALSE)-$B2,2)+POWER(VLOOKUP(I$1,'Ral Classic'!$A:$D,COLUMN('Ral Classic'!$C1),FALSE)-$C2,2)+POWER(VLOOKUP(I$1,'Ral Classic'!$A:$D,COLUMN('Ral Classic'!$D1),FALSE)-$D2,2),1/2) -> 298.94648 | J2: =POWER(POWER(VLOOKUP(J$1,'Ral Classic'!$A:$D,COLUMN('Ral Classic'!$B1),FALSE)-$B2,2)+POWER(VLOOKUP(J$1,'Ral Classic'!$A:$D,COLUMN('Ral Classic'!$C1),FALSE)-$C2,2)+POWER(VLOOKUP(J$1,'Ral Classic'!$A:$D,COLUMN('Ral Classic'!$D1),FALSE)-$D2,2),1/2) -> 307.1091 | K2: =POWER(POWER(VLOOKUP(K$1,'Ral Classic'!$A:$D,COLUMN('Ral Classic'!$B1),FALSE)-$B2,2)+POWER(VLOOKUP(K$1,'Ral Classic'!$A:$D,COLUMN('Ral Classic'!$C1),FALSE)-$C2,2)+POWER(VLOOKUP(K$1,'Ral Classic'!$A:$D,COLUMN('Ral Classic'!$D1),FALSE)-$D2,2),1/2) -> 394.01777 | L2: =POWER(POWER(VLOOKUP(L$1,'Ral Classic'!$A:$D,COLUMN('Ral Classic'!$B1),FALSE)-$B2,2)+POWER(VLOOKUP(L$1,'Ral Classic'!$A:$D,COLUMN('Ral Classic'!$C1),FALSE)-$C2,2)+POWER(VLOOKUP(L$1,'Ral Classic'!$A:$D,COLUMN('Ral Classic'!$D1),FALSE)-$D2,2),1/2) -> 376.79305 | M2: =POWER(POWER(VLOOKUP(M$1,'Ral Classic'!$A:$D,COLUMN('Ral Classic'!$B1),FALSE)-$B2,2)+POWER(VLOOKUP(M$1,'Ral Classic'!$A:$D,COLUMN('Ral Classic'!$C1),FALSE)-$C2,2)+POWER(VLOOKUP(M$1,'Ral Classic'!$A:$D,COLUMN('Ral Classic'!$D1),FALSE)-$D2,2),1/2) -> 355.52496 | N2: =POWER(POWER(VLOOKUP(N$1,'Ral Classic'!$A:$D,COLUMN('Ral Classic'!$B1),FALSE)-$B2,2)+POWER(VLOOKUP(N$1,'Ral Classic'!$A:$D,COLUMN('Ral Classic'!$C1),FALSE)-$C2,2)+POWER(VLOOKUP(N$1,'Ral Classic'!$A:$D,COLUMN('Ral Classic'!$D1),FALSE)-$D2,2),1/2) -> 369.91486 | O2: =POWER(POWER(VLOOKUP(O$1,'Ral Classic'!$A:$D,COLUMN('Ral Classic'!$B1),FALSE)-$B2,2)+POWER(VLOOKUP(O$1,'Ral Classic'!$A:$D,COLUMN('Ral Classic'!$C1),FALSE)-$C2,2)+POWER(VLOOKUP(O$1,'Ral Classic'!$A:$D,COLUMN('Ral Classic'!$D1),FALSE)-$D2,2),1/2) -> 372.08736 | ... HL2: =POWER(POWER(VLOOKUP(HL$1,'Ral Classic'!$A:$D,COLUMN('Ral Classic'!$B1),FALSE)-$B2,2)+POWER(VLOOKUP(HL$1,'Ral Classic'!$A:$D,COLUMN('Ral Classic'!$C1),FALSE)-$C2,2)+POWER(VLOOKUP(HL$1,'Ral Classic'!$A:$D,COLUMN('Ral Classic'!$D1),FALSE)-$D2,2),1/2) -> 217.85087
A3: 1 | B3: 16 | C3: 16 | D3: 16 | E3: =MIN(H3:HL3) -> 2.8284271 | F3: {=INDEX($1:$1,1,CELL("столбец",INDEX(H3:HL3,MATCH(MIN(H3:HL3),H3:HL3,0))))} -> RAL 9005 | G3: =VLOOKUP(F3,'Ral Classic'!$A:$N,COLUMN('Ral Classic'!$L$1),FALSE) -> Jet black | H3: =POWER(POWER(VLOOKUP(H$1,'Ral Classic'!$A:$D,COLUMN('Ral Classic'!$B2),FALSE)-$B3,2)+POWER(VLOOKUP(H$1,'Ral Classic'!$A:$D,COLUMN('Ral Classic'!$C2),FALSE)-$C3,2)+POWER(VLOOKUP(H$1,'Ral Classic'!$A:$D,COLUMN('Ral Classic'!$D2),FALSE)-$D3,2),1/2) -> 281.10674 | I3: =POWER(POWER(VLOOKUP(I$1,'Ral Classic'!$A:$D,COLUMN('Ral Classic'!$B2),FALSE)-$B3,2)+POWER(VLOOKUP(I$1,'Ral Classic'!$A:$D,COLUMN('Ral Classic'!$C2),FALSE)-$C3,2)+POWER(VLOOKUP(I$1,'Ral Classic'!$A:$D,COLUMN('Ral Classic'!$D2),FALSE)-$D3,2),1/2) -> 275.53584 | J3: =POWER(POWER(VLOOKUP(J$1,'Ral Classic'!$A:$D,COLUMN('Ral Classic'!$B2),FALSE)-$B3,2)+POWER(VLOOKUP(J$1,'Ral Classic'!$A:$D,COLUMN('Ral Classic'!$C2),FALSE)-$C3,2)+POWER(VLOOKUP(J$1,'Ral Classic'!$A:$D,COLUMN('Ral Classic'!$D2),FALSE)-$D3,2),1/2) -> 264.57702 | K3: =POWER(POWER(VLOOKUP(K$1,'Ral Classic'!$A:$D,COLUMN('Ral Classic'!$B2),FALSE)-$B3,2)+POWER(VLOOKUP(K$1,'Ral Classic'!$A:$D,COLUMN('Ral Classic'!$C2),FALSE)-$C3,2)+POWER(VLOOKUP(K$1,'Ral Classic'!$A:$D,COLUMN('Ral Classic'!$D2),FALSE)-$D3,2),1/2) -> 278.6557 | L3: =POWER(POWER(VLOOKUP(L$1,'Ral Classic'!$A:$D,COLUMN('Ral Classic'!$B2),FALSE)-$B3,2)+POWER(VLOOKUP(L$1,'Ral Classic'!$A:$D,COLUMN('Ral Classic'!$C2),FALSE)-$C3,2)+POWER(VLOOKUP(L$1,'Ral Classic'!$A:$D,COLUMN('Ral Classic'!$D2),FALSE)-$D3,2),1/2) -> 255.66384 | M3: =POWER(POWER(VLOOKUP(M$1,'Ral Classic'!$A:$D,COLUMN('Ral Classic'!$B2),FALSE)-$B3,2)+POWER(VLOOKUP(M$1,'Ral Classic'!$A:$D,COLUMN('Ral Classic'!$C2),FALSE)-$C3,2)+POWER(VLOOKUP(M$1,'Ral Classic'!$A:$D,COLUMN('Ral Classic'!$D2),FALSE)-$D3,2),1/2) -> 226.0553 | N3: =POWER(POWER(VLOOKUP(N$1,'Ral Classic'!$A:$D,COLUMN('Ral Classic'!$B2),FALSE)-$B3,2)+POWER(VLOOKUP(N$1,'Ral Classic'!$A:$D,COLUMN('Ral Classic'!$C2),FALSE)-$C3,2)+POWER(VLOOKUP(N$1,'Ral Classic'!$A:$D,COLUMN('Ral Classic'!$D2),FALSE)-$D3,2),1/2) -> 246.45486 | O3: =POWER(POWER(VLOOKUP(O$1,'Ral Classic'!$A:$D,COLUMN('Ral Classic'!$B2),FALSE)-$B3,2)+POWER(VLOOKUP(O$1,'Ral Classic'!$A:$D,COLUMN('Ral Classic'!$C2),FALSE)-$C3,2)+POWER(VLOOKUP(O$1,'Ral Classic'!$A:$D,COLUMN('Ral Classic'!$D2),FALSE)-$D3,2),1/2) -> 249.57564 | ... HL3: =POWER(POWER(VLOOKUP(HL$1,'Ral Classic'!$A:$D,COLUMN('Ral Classic'!$B2),FALSE)-$B3,2)+POWER(VLOOKUP(HL$1,'Ral Classic'!$A:$D,COLUMN('Ral Classic'!$C2),FALSE)-$C3,2)+POWER(VLOOKUP(HL$1,'Ral Classic'!$A:$D,COLUMN('Ral Classic'!$D2),FALSE)-$D3,2),1/2) -> 183.60283
A4: 2 | B4: 32 | C4: 32 | D4: 32 | E4: =MIN(H4:HL4) -> 10.198039 | F4: {=INDEX($1:$1,1,CELL("столбец",INDEX(H4:HL4,MATCH(MIN(H4:HL4),H4:HL4,0))))} -> RAL 5004 | G4: =VLOOKUP(F4,'Ral Classic'!$A:$N,COLUMN('Ral Classic'!$L$1),FALSE) -> Black blue | H4: =POWER(POWER(VLOOKUP(H$1,'Ral Classic'!$A:$D,COLUMN('Ral Classic'!$B3),FALSE)-$B4,2)+POWER(VLOOKUP(H$1,'Ral Classic'!$A:$D,COLUMN('Ral Classic'!$C3),FALSE)-$C4,2)+POWER(VLOOKUP(H$1,'Ral Classic'!$A:$D,COLUMN('Ral Classic'!$D3),FALSE)-$D4,2),1/2) -> 253.89171 | I4: =POWER(POWER(VLOOKUP(I$1,'Ral Classic'!$A:$D,COLUMN('Ral Classic'!$B3),FALSE)-$B4,2)+POWER(VLOOKUP(I$1,'Ral Classic'!$A:$D,COLUMN('Ral Classic'!$C3),FALSE)-$C4,2)+POWER(VLOOKUP(I$1,'Ral Classic'!$A:$D,COLUMN('Ral Classic'!$D3),FALSE)-$D4,2),1/2) -> 248.419 | J4: =POWER(POWER(VLOOKUP(J$1,'Ral Classic'!$A:$D,COLUMN('Ral Classic'!$B3),FALSE)-$B4,2)+POWER(VLOOKUP(J$1,'Ral Classic'!$A:$D,COLUMN('Ral Classic'!$C3),FALSE)-$C4,2)+POWER(VLOOKUP(J$1,'Ral Classic'!$A:$D,COLUMN('Ral Classic'!$D3),FALSE)-$D4,2),1/2) -> 238.02731 | K4: =POWER(POWER(VLOOKUP(K$1,'Ral Classic'!$A:$D,COLUMN('Ral Classic'!$B3),FALSE)-$B4,2)+POWER(VLOOKUP(K$1,'Ral Classic'!$A:$D,COLUMN('Ral Classic'!$C3),FALSE)-$C4,2)+POWER(VLOOKUP(K$1,'Ral Classic'!$A:$D,COLUMN('Ral Classic'!$D3),FALSE)-$D4,2),1/2) -> 258.08719 | L4: =POWER(POWER(VLOOKUP(L$1,'Ral Classic'!$A:$D,COLUMN('Ral Classic'!$B3),FALSE)-$B4,2)+POWER(VLOOKUP(L$1,'Ral Classic'!$A:$D,COLUMN('Ral Classic'!$C3),FALSE)-$C4,2)+POWER(VLOOKUP(L$1,'Ral Classic'!$A:$D,COLUMN('Ral Classic'!$D3),FALSE)-$D4,2),1/2) -> 235.19354 | M4: =POWER(POWER(VLOOKUP(M$1,'Ral Classic'!$A:$D,COLUMN('Ral Classic'!$B3),FALSE)-$B4,2)+POWER(VLOOKUP(M$1,'Ral Classic'!$A:$D,COLUMN('Ral Classic'!$C3),FALSE)-$C4,2)+POWER(VLOOKUP(M$1,'Ral Classic'!$A:$D,COLUMN('Ral Classic'!$D3),FALSE)-$D4,2),1/2) -> 205.8276 | N4: =POWER(POWER(VLOOKUP(N$1,'Ral Classic'!$A:$D,COLUMN('Ral Classic'!$B3),FALSE)-$B4,2)+POWER(VLOOKUP(N$1,'Ral Classic'!$A:$D,COLUMN('Ral Classic'!$C3),FALSE)-$C4,2)+POWER(VLOOKUP(N$1,'Ral Classic'!$A:$D,COLUMN('Ral Classic'!$D3),FALSE)-$D4,2),1/2) -> 226.28301 | O4: =POWER(POWER(VLOOKUP(O$1,'Ral Classic'!$A:$D,COLUMN('Ral Classic'!$B3),FALSE)-$B4,2)+POWER(VLOOKUP(O$1,'Ral Classic'!$A:$D,COLUMN('Ral Classic'!$C3),FALSE)-$C4,2)+POWER(VLOOKUP(O$1,'Ral Classic'!$A:$D,COLUMN('Ral Classic'!$D3),FALSE)-$D4,2),1/2) -> 229.53867 | ... HL4: =POWER(POWER(VLOOKUP(HL$1,'Ral Classic'!$A:$D,COLUMN('Ral Classic'!$B3),FALSE)-$B4,2)+POWER(VLOOKUP(HL$1,'Ral Classic'!$A:$D,COLUMN('Ral Classic'!$C3),FALSE)-$C4,2)+POWER(VLOOKUP(HL$1,'Ral Classic'!$A:$D,COLUMN('Ral Classic'!$D3),FALSE)-$D4,2),1/2) -> 155.89099
A5: 3 | B5: 48 | C5: 48 | D5: 48 | E5: =MIN(H5:HL5) -> 4.472136 | F5: {=INDEX($1:$1,1,CELL("столбец",INDEX(H5:HL5,MATCH(MIN(H5:HL5),H5:HL5,0))))} -> RAL 7021 | G5: =VLOOKUP(F5,'Ral Classic'!$A:$N,COLUMN('Ral Classic'!$L$1),FALSE) -> Black grey | H5: =POWER(POWER(VLOOKUP(H$1,'Ral Classic'!$A:$D,COLUMN('Ral Classic'!$B4),FALSE)-$B5,2)+POWER(VLOOKUP(H$1,'Ral Classic'!$A:$D,COLUMN('Ral Classic'!$C4),FALSE)-$C5,2)+POWER(VLOOKUP(H$1,'Ral Classic'!$A:$D,COLUMN('Ral Classic'!$D4),FALSE)-$D5,2),1/2) -> 226.79727 | I5: =POWER(POWER(VLOOKUP(I$1,'Ral Classic'!$A:$D,COLUMN('Ral Classic'!$B4),FALSE)-$B5,2)+POWER(VLOOKUP(I$1,'Ral Classic'!$A:$D,COLUMN('Ral Classic'!$C4),FALSE)-$C5,2)+POWER(VLOOKUP(I$1,'Ral Classic'!$A:$D,COLUMN('Ral Classic'!$D4),FALSE)-$D5,2),1/2) -> 221.44977 | J5: =POWER(POWER(VLOOKUP(J$1,'Ral Classic'!$A:$D,COLUMN('Ral Classic'!$B4),FALSE)-$B5,2)+POWER(VLOOKUP(J$1,'Ral Classic'!$A:$D,COLUMN('Ral Classic'!$C4),FALSE)-$C5,2)+POWER(VLOOKUP(J$1,'Ral Classic'!$A:$D,COLUMN('Ral Classic'!$D4),FALSE)-$D5,2),1/2) -> 211.77582 | K5: =POWER(POWER(VLOOKUP(K$1,'Ral Classic'!$A:$D,COLUMN('Ral Classic'!$B4),FALSE)-$B5,2)+POWER(VLOOKUP(K$1,'Ral Classic'!$A:$D,COLUMN('Ral Classic'!$C4),FALSE)-$C5,2)+POWER(VLOOKUP(K$1,'Ral Classic'!$A:$D,COLUMN('Ral Classic'!$D4),FALSE)-$D5,2),1/2) -> 238.96652 | L5: =POWER(POWER(VLOOKUP(L$1,'Ral Classic'!$A:$D,COLUMN('Ral Classic'!$B4),FALSE)-$B5,2)+POWER(VLOOKUP(L$1,'Ral Classic'!$A:$D,COLUMN('Ral Classic'!$C4),FALSE)-$C5,2)+POWER(VLOOKUP(L$1,'Ral Classic'!$A:$D,COLUMN('Ral Classic'!$D4),FALSE)-$D5,2),1/2) -> 216.34232 | M5: =POWER(POWER(VLOOKUP(M$1,'Ral Classic'!$A:$D,COLUMN('Ral Classic'!$B4),FALSE)-$B5,2)+POWER(VLOOKUP(M$1,'Ral Classic'!$A:$D,COLUMN('Ral Classic'!$C4),FALSE)-$C5,2)+POWER(VLOOKUP(M$1,'Ral Classic'!$A:$D,COLUMN('Ral Classic'!$D4),FALSE)-$D5,2),1/2) -> 187.52333 | N5: =POWER(POWER(VLOOKUP(N$1,'Ral Classic'!$A:$D,COLUMN('Ral Classic'!$B4),FALSE)-$B5,2)+POWER(VLOOKUP(N$1,'Ral Classic'!$A:$D,COLUMN('Ral Classic'!$C4),FALSE)-$C5,2)+POWER(VLOOKUP(N$1,'Ral Classic'!$A:$D,COLUMN('Ral Classic'!$D4),FALSE)-$D5,2),1/2) -> 207.85572 | O5: =POWER(POWER(VLOOKUP(O$1,'Ral Classic'!$A:$D,COLUMN('Ral Classic'!$B4),FALSE)-$B5,2)+POWER(VLOOKUP(O$1,'Ral Classic'!$A:$D,COLUMN('Ral Classic'!$C4),FALSE)-$C5,2)+POWER(VLOOKUP(O$1,'Ral Classic'!$A:$D,COLUMN('Ral Classic'!$D4),FALSE)-$D5,2),1/2) -> 211.24393 | ... HL5: =POWER(POWER(VLOOKUP(HL$1,'Ral Classic'!$A:$D,COLUMN('Ral Classic'!$B4),FALSE)-$B5,2)+POWER(VLOOKUP(HL$1,'Ral Classic'!$A:$D,COLUMN('Ral Classic'!$C4),FALSE)-$C5,2)+POWER(VLOOKUP(HL$1,'Ral Classic'!$A:$D,COLUMN('Ral Classic'!$D4),FALSE)-$D5,2),1/2) -> 128.17956
A6: 4 | B6: 64 | C6: 64 | D6: 64 | E6: =MIN(H6:HL6) -> 8.4852814 | F6: {=INDEX($1:$1,1,CELL("столбец",INDEX(H6:HL6,MATCH(MIN(H6:HL6),H6:HL6,0))))} -> RAL 7016 | G6: =VLOOKUP(F6,'Ral Classic'!$A:$N,COLUMN('Ral Classic'!$L$1),FALSE) -> Anthracite grey | H6: =POWER(POWER(VLOOKUP(H$1,'Ral Classic'!$A:$D,COLUMN('Ral Classic'!$B5),FALSE)-$B6,2)+POWER(VLOOKUP(H$1,'Ral Classic'!$A:$D,COLUMN('Ral Classic'!$C5),FALSE)-$C6,2)+POWER(VLOOKUP(H$1,'Ral Classic'!$A:$D,COLUMN('Ral Classic'!$D5),FALSE)-$D6,2),1/2) -> 199.87246 | I6: =POWER(POWER(VLOOKUP(I$1,'Ral Classic'!$A:$D,COLUMN('Ral Classic'!$B5),FALSE)-$B6,2)+POWER(VLOOKUP(I$1,'Ral Classic'!$A:$D,COLUMN('Ral Classic'!$C5),FALSE)-$C6,2)+POWER(VLOOKUP(I$1,'Ral Classic'!$A:$D,COLUMN('Ral Classic'!$D5),FALSE)-$D6,2),1/2) -> 194.6895 | J6: =POWER(POWER(VLOOKUP(J$1,'Ral Classic'!$A:$D,COLUMN('Ral Classic'!$B5),FALSE)-$B6,2)+POWER(VLOOKUP(J$1,'Ral Classic'!$A:$D,COLUMN('Ral Classic'!$C5),FALSE)-$C6,2)+POWER(VLOOKUP(J$1,'Ral Classic'!$A:$D,COLUMN('Ral Classic'!$D5),FALSE)-$D6,2),1/2) -> 185.94892 | K6: =POWER(POWER(VLOOKUP(K$1,'Ral Classic'!$A:$D,COLUMN('Ral Classic'!$B5),FALSE)-$B6,2)+POWER(VLOOKUP(K$1,'Ral Classic'!$A:$D,COLUMN('Ral Classic'!$C5),FALSE)-$C6,2)+POWER(VLOOKUP(K$1,'Ral Classic'!$A:$D,COLUMN('Ral Classic'!$D5),FALSE)-$D6,2),1/2) -> 221.66867 | L6: =POWER(POWER(VLOOKUP(L$1,'Ral Classic'!$A:$D,COLUMN('Ral Classic'!$B5),FALSE)-$B6,2)+POWER(VLOOKUP(L$1,'Ral Classic'!$A:$D,COLUMN('Ral Classic'!$C5),FALSE)-$C6,2)+POWER(VLOOKUP(L$1,'Ral Classic'!$A:$D,COLUMN('Ral Classic'!$D5),FALSE)-$D6,2),1/2) -> 199.56954 | M6: =POWER(POWER(VLOOKUP(M$1,'Ral Classic'!$A:$D,COLUMN('Ral Classic'!$B5),FALSE)-$B6,2)+POWER(VLOOKUP(M$1,'Ral Classic'!$A:$D,COLUMN('Ral Classic'!$C5),FALSE)-$C6,2)+POWER(VLOOKUP(M$1,'Ral Classic'!$A:$D,COLUMN('Ral Classic'!$D5),FALSE)-$D6,2),1/2) -> 171.75855 | N6: =POWER(POWER(VLOOKUP(N$1,'Ral Classic'!$A:$D,COLUMN('Ral Classic'!$B5),FALSE)-$B6,2)+POWER(VLOOKUP(N$1,'Ral Classic'!$A:$D,COLUMN('Ral Classic'!$C5),FALSE)-$C6,2)+POWER(VLOOKUP(N$1,'Ral Classic'!$A:$D,COLUMN('Ral Classic'!$D5),FALSE)-$D6,2),1/2) -> 191.67681 | O6: =POWER(POWER(VLOOKUP(O$1,'Ral Classic'!$A:$D,COLUMN('Ral Classic'!$B5),FALSE)-$B6,2)+POWER(VLOOKUP(O$1,'Ral Classic'!$A:$D,COLUMN('Ral Classic'!$C5),FALSE)-$C6,2)+POWER(VLOOKUP(O$1,'Ral Classic'!$A:$D,COLUMN('Ral Classic'!$D5),FALSE)-$D6,2),1/2) -> 195.18197 | ... HL6: =POWER(POWER(VLOOKUP(HL$1,'Ral Classic'!$A:$D,COLUMN('Ral Classic'!$B5),FALSE)-$B6,2)+POWER(VLOOKUP(HL$1,'Ral Classic'!$A:$D,COLUMN('Ral Classic'!$C5),FALSE)-$C6,2)+POWER(VLOOKUP(HL$1,'Ral Classic'!$A:$D,COLUMN('Ral Classic'!$D5),FALSE)-$D6,2),1/2) -> 100.4689
A7: 5 | B7: 80 | C7: 80 | D7: 80 | E7: =MIN(H7:HL7) -> 2.236068 | F7: {=INDEX($1:$1,1,CELL("столбец",INDEX(H7:HL7,MATCH(MIN(H7:HL7),H7:HL7,0))))} -> RAL 7043 | G7: =VLOOKUP(F7,'Ral Classic'!$A:$N,COLUMN('Ral Classic'!$L$1),FALSE) -> Traffic grey B | H7: =POWER(POWER(VLOOKUP(H$1,'Ral Classic'!$A:$D,COLUMN('Ral Classic'!$B6),FALSE)-$B7,2)+POWER(VLOOKUP(H$1,'Ral Classic'!$A:$D,COLUMN('Ral Classic'!$C6),FALSE)-$C7,2)+POWER(VLOOKUP(H$1,'Ral Classic'!$A:$D,COLUMN('Ral Classic'!$D6),FALSE)-$D7,2),1/2) -> 173.19642 | I7: =POWER(POWER(VLOOKUP(I$1,'Ral Classic'!$A:$D,COLUMN('Ral Classic'!$B6),FALSE)-$B7,2)+POWER(VLOOKUP(I$1,'Ral Classic'!$A:$D,COLUMN('Ral Classic'!$C6),FALSE)-$C7,2)+POWER(VLOOKUP(I$1,'Ral Classic'!$A:$D,COLUMN('Ral Classic'!$D6),FALSE)-$D7,2),1/2) -> 168.23793 | J7: =POWER(POWER(VLOOKUP(J$1,'Ral Classic'!$A:$D,COLUMN('Ral Classic'!$B6),FALSE)-$B7,2)+POWER(VLOOKUP(J$1,'Ral Classic'!$A:$D,COLUMN('Ral Classic'!$C6),FALSE)-$C7,2)+POWER(VLOOKUP(J$1,'Ral Classic'!$A:$D,COLUMN('Ral Classic'!$D6),FALSE)-$D7,2),1/2) -> 160.75136 | K7: =POWER(POWER(VLOOKUP(K$1,'Ral Classic'!$A:$D,COLUMN('Ral Classic'!$B6),FALSE)-$B7,2)+POWER(VLOOKUP(K$1,'Ral Classic'!$A:$D,COLUMN('Ral Classic'!$C6),FALSE)-$C7,2)+POWER(VLOOKUP(K$1,'Ral Classic'!$A:$D,COLUMN('Ral Classic'!$D6),FALSE)-$D7,2),1/2) -> 206.65188 | L7: =POWER(POWER(VLOOKUP(L$1,'Ral Classic'!$A:$D,COLUMN('Ral Classic'!$B6),FALSE)-$B7,2)+POWER(VLOOKUP(L$1,'Ral Classic'!$A:$D,COLUMN('Ral Classic'!$C6),FALSE)-$C7,2)+POWER(VLOOKUP(L$1,'Ral Classic'!$A:$D,COLUMN('Ral Classic'!$D6),FALSE)-$D7,2),1/2) -> 185.44002 | M7: =POWER(POWER(VLOOKUP(M$1,'Ral Classic'!$A:$D,COLUMN('Ral Classic'!$B6),FALSE)-$B7,2)+POWER(VLOOKUP(M$1,'Ral Classic'!$A:$D,COLUMN('Ral Classic'!$C6),FALSE)-$C7,2)+POWER(VLOOKUP(M$1,'Ral Classic'!$A:$D,COLUMN('Ral Classic'!$D6),FALSE)-$D7,2),1/2) -> 159.28905 | N7: =POWER(POWER(VLOOKUP(N$1,'Ral Classic'!$A:$D,COLUMN('Ral Classic'!$B6),FALSE)-$B7,2)+POWER(VLOOKUP(N$1,'Ral Classic'!$A:$D,COLUMN('Ral Classic'!$C6),FALSE)-$C7,2)+POWER(VLOOKUP(N$1,'Ral Classic'!$A:$D,COLUMN('Ral Classic'!$D6),FALSE)-$D7,2),1/2) -> 178.35919 | O7: =POWER(POWER(VLOOKUP(O$1,'Ral Classic'!$A:$D,COLUMN('Ral Classic'!$B6),FALSE)-$B7,2)+POWER(VLOOKUP(O$1,'Ral Classic'!$A:$D,COLUMN('Ral Classic'!$C6),FALSE)-$C7,2)+POWER(VLOOKUP(O$1,'Ral Classic'!$A:$D,COLUMN('Ral Classic'!$D6),FALSE)-$D7,2),1/2) -> 181.94505 | ... HL7: =POWER(POWER(VLOOKUP(HL$1,'Ral Classic'!$A:$D,COLUMN('Ral Classic'!$B6),FALSE)-$B7,2)+POWER(VLOOKUP(HL$1,'Ral Classic'!$A:$D,COLUMN('Ral Classic'!$C6),FALSE)-$C7,2)+POWER(VLOOKUP(HL$1,'Ral Classic'!$A:$D,COLUMN('Ral Classic'!$D6),FALSE)-$D7,2),1/2) -> 72.759879
A8: 6 | B8: 100 | C8: 100 | D8: 100 | E8: =MIN(H8:HL8) -> 8.7177979 | F8: {=INDEX($1:$1,1,CELL("столбец",INDEX(H8:HL8,MATCH(MIN(H8:HL8),H8:HL8,0))))} -> RAL 7039 | G8: =VLOOKUP(F8,'Ral Classic'!$A:$N,COLUMN('Ral Classic'!$L$1),FALSE) -> Quartz grey | H8: =POWER(POWER(VLOOKUP(H$1,'Ral Classic'!$A:$D,COLUMN('Ral Classic'!$B7),FALSE)-$B8,2)+POWER(VLOOKUP(H$1,'Ral Classic'!$A:$D,COLUMN('Ral Classic'!$C7),FALSE)-$C8,2)+POWER(VLOOKUP(H$1,'Ral Classic'!$A:$D,COLUMN('Ral Classic'!$D7),FALSE)-$D8,2),1/2) -> 140.41724 | I8: =POWER(POWER(VLOOKUP(I$1,'Ral Classic'!$A:$D,COLUMN('Ral Classic'!$B7),FALSE)-$B8,2)+POWER(VLOOKUP(I$1,'Ral Classic'!$A:$D,COLUMN('Ral Classic'!$C7),FALSE)-$C8,2)+POWER(VLOOKUP(I$1,'Ral Classic'!$A:$D,COLUMN('Ral Classic'!$D7),FALSE)-$D8,2),1/2) -> 135.8823 | J8: =POWER(POWER(VLOOKUP(J$1,'Ral Classic'!$A:$D,COLUMN('Ral Classic'!$B7),FALSE)-$B8,2)+POWER(VLOOKUP(J$1,'Ral Classic'!$A:$D,COLUMN('Ral Classic'!$C7),FALSE)-$C8,2)+POWER(VLOOKUP(J$1,'Ral Classic'!$A:$D,COLUMN('Ral Classic'!$D7),FALSE)-$D8,2),1/2) -> 130.6943 | K8: =POWER(POWER(VLOOKUP(K$1,'Ral Classic'!$A:$D,COLUMN('Ral Classic'!$B7),FALSE)-$B8,2)+POWER(VLOOKUP(K$1,'Ral Classic'!$A:$D,COLUMN('Ral Classic'!$C7),FALSE)-$C8,2)+POWER(VLOOKUP(K$1,'Ral Classic'!$A:$D,COLUMN('Ral Classic'!$D7),FALSE)-$D8,2),1/2) -> 191.89841 | L8: =POWER(POWER(VLOOKUP(L$1,'Ral Classic'!$A:$D,COLUMN('Ral Classic'!$B7),FALSE)-$B8,2)+POWER(VLOOKUP(L$1,'Ral Classic'!$A:$D,COLUMN('Ral Classic'!$C7),FALSE)-$C8,2)+POWER(VLOOKUP(L$1,'Ral Classic'!$A:$D,COLUMN('Ral Classic'!$D7),FALSE)-$D8,2),1/2) -> 172.47609 | M8: =POWER(POWER(VLOOKUP(M$1,'Ral Classic'!$A:$D,COLUMN('Ral Classic'!$B7),FALSE)-$B8,2)+POWER(VLOOKUP(M$1,'Ral Classic'!$A:$D,COLUMN('Ral Classic'!$C7),FALSE)-$C8,2)+POWER(VLOOKUP(M$1,'Ral Classic'!$A:$D,COLUMN('Ral Classic'!$D7),FALSE)-$D8,2),1/2) -> 149.57607 | N8: =POWER(POWER(VLOOKUP(N$1,'Ral Classic'!$A:$D,COLUMN('Ral Classic'!$B7),FALSE)-$B8,2)+POWER(VLOOKUP(N$1,'Ral Classic'!$A:$D,COLUMN('Ral Classic'!$C7),FALSE)-$C8,2)+POWER(VLOOKUP(N$1,'Ral Classic'!$A:$D,COLUMN('Ral Classic'!$D7),FALSE)-$D8,2),1/2) -> 166.7693 | O8: =POWER(POWER(VLOOKUP(O$1,'Ral Classic'!$A:$D,COLUMN('Ral Classic'!$B7),FALSE)-$B8,2)+POWER(VLOOKUP(O$1,'Ral Classic'!$A:$D,COLUMN('Ral Classic'!$C7),FALSE)-$C8,2)+POWER(VLOOKUP(O$1,'Ral Classic'!$A:$D,COLUMN('Ral Classic'!$D7),FALSE)-$D8,2),1/2) -> 170.36432 | ... HL8: =POWER(POWER(VLOOKUP(HL$1,'Ral Classic'!$A:$D,COLUMN('Ral Classic'!$B7),FALSE)-$B8,2)+POWER(VLOOKUP(HL$1,'Ral Classic'!$A:$D,COLUMN('Ral Classic'!$C7),FALSE)-$C8,2)+POWER(VLOOKUP(HL$1,'Ral Classic'!$A:$D,COLUMN('Ral Classic'!$D7),FALSE)-$D8,2),1/2) -> 38.131352
A9: 7 | B9: 116 | C9: 116 | D9: 116 | E9: =MIN(H9:HL9) -> 10.488088 | F9: {=INDEX($1:$1,1,CELL("столбец",INDEX(H9:HL9,MATCH(MIN(H9:HL9),H9:HL9,0))))} -> RAL 9023 | G9: =VLOOKUP(F9,'Ral Classic'!$A:$N,COLUMN('Ral Classic'!$L$1),FALSE) -> Pearl dark grey | H9: =POWER(POWER(VLOOKUP(H$1,'Ral Classic'!$A:$D,COLUMN('Ral Classic'!$B8),FALSE)-$B9,2)+POWER(VLOOKUP(H$1,'Ral Classic'!$A:$D,COLUMN('Ral Classic'!$C8),FALSE)-$C9,2)+POWER(VLOOKUP(H$1,'Ral Classic'!$A:$D,COLUMN('Ral Classic'!$D8),FALSE)-$D9,2),1/2) -> 114.98261 | I9: =POWER(POWER(VLOOKUP(I$1,'Ral Classic'!$A:$D,COLUMN('Ral Classic'!$B8),FALSE)-$B9,2)+POWER(VLOOKUP(I$1,'Ral Classic'!$A:$D,COLUMN('Ral Classic'!$C8),FALSE)-$C9,2)+POWER(VLOOKUP(I$1,'Ral Classic'!$A:$D,COLUMN('Ral Classic'!$D8),FALSE)-$D9,2),1/2) -> 110.9955 | J9: =POWER(POWER(VLOOKUP(J$1,'Ral Classic'!$A:$D,COLUMN('Ral Classic'!$B8),FALSE)-$B9,2)+POWER(VLOOKUP(J$1,'Ral Classic'!$A:$D,COLUMN('Ral Classic'!$C8),FALSE)-$C9,2)+POWER(VLOOKUP(J$1,'Ral Classic'!$A:$D,COLUMN('Ral Classic'!$D8),FALSE)-$D9,2),1/2) -> 108.63241 | K9: =POWER(POWER(VLOOKUP(K$1,'Ral Classic'!$A:$D,COLUMN('Ral Classic'!$B8),FALSE)-$B9,2)+POWER(VLOOKUP(K$1,'Ral Classic'!$A:$D,COLUMN('Ral Classic'!$C8),FALSE)-$C9,2)+POWER(VLOOKUP(K$1,'Ral Classic'!$A:$D,COLUMN('Ral Classic'!$D8),FALSE)-$D9,2),1/2) -> 183.98098 | L9: =POWER(POWER(VLOOKUP(L$1,'Ral Classic'!$A:$D,COLUMN('Ral Classic'!$B8),FALSE)-$B9,2)+POWER(VLOOKUP(L$1,'Ral Classic'!$A:$D,COLUMN('Ral Classic'!$C8),FALSE)-$C9,2)+POWER(VLOOKUP(L$1,'Ral Classic'!$A:$D,COLUMN('Ral Classic'!$D8),FALSE)-$D9,2),1/2) -> 166.62533 | M9: =POWER(POWER(VLOOKUP(M$1,'Ral Classic'!$A:$D,COLUMN('Ral Classic'!$B8),FALSE)-$B9,2)+POWER(VLOOKUP(M$1,'Ral Classic'!$A:$D,COLUMN('Ral Classic'!$C8),FALSE)-$C9,2)+POWER(VLOOKUP(M$1,'Ral Classic'!$A:$D,COLUMN('Ral Classic'!$D8),FALSE)-$D9,2),1/2) -> 147.31259 | N9: =POWER(POWER(VLOOKUP(N$1,'Ral Classic'!$A:$D,COLUMN('Ral Classic'!$B8),FALSE)-$B9,2)+POWER(VLOOKUP(N$1,'Ral Classic'!$A:$D,COLUMN('Ral Classic'!$C8),FALSE)-$C9,2)+POWER(VLOOKUP(N$1,'Ral Classic'!$A:$D,COLUMN('Ral Classic'!$D8),FALSE)-$D9,2),1/2) -> 162.29603 | O9: =POWER(POWER(VLOOKUP(O$1,'Ral Classic'!$A:$D,COLUMN('Ral Classic'!$B8),FALSE)-$B9,2)+POWER(VLOOKUP(O$1,'Ral Classic'!$A:$D,COLUMN('Ral Classic'!$C8),FALSE)-$C9,2)+POWER(VLOOKUP(O$1,'Ral Classic'!$A:$D,COLUMN('Ral Classic'!$D8),FALSE)-$D9,2),1/2) -> 165.79505 | ... HL9: =POWER(POWER(VLOOKUP(HL$1,'Ral Classic'!$A:$D,COLUMN('Ral Classic'!$B8),FALSE)-$B9,2)+POWER(VLOOKUP(HL$1,'Ral Classic'!$A:$D,COLUMN('Ral Classic'!$C8),FALSE)-$C9,2)+POWER(VLOOKUP(HL$1,'Ral Classic'!$A:$D,COLUMN('Ral Classic'!$D8),FALSE)-$D9,2),1/2) -> 10.488088
A10: 8 | B10: 132 | C10: 132 | D10: 132 | E10: =MIN(H10:HL10) -> 1.7320508 | F10: {=INDEX($1:$1,1,CELL("столбец",INDEX(H10:HL10,MATCH(MIN(H10:HL10),H10:HL10,0))))} -> RAL 9022 | G10: =VLOOKUP(F10,'Ral Classic'!$A:$N,COLUMN('Ral Classic'!$L$1),FALSE) -> Pearl light grey | H10: =POWER(POWER(VLOOKUP(H$1,'Ral Classic'!$A:$D,COLUMN('Ral Classic'!$B9),FALSE)-$B10,2)+POWER(VLOOKUP(H$1,'Ral Classic'!$A:$D,COLUMN('Ral Classic'!$C9),FALSE)-$C10,2)+POWER(VLOOKUP(H$1,'Ral Classic'!$A:$D,COLUMN('Ral Classic'!$D9),FALSE)-$D10,2),1/2) -> 90.890043 | I10: =POWER(POWER(VLOOKUP(I$1,'Ral Classic'!$A:$D,COLUMN('Ral Classic'!$B9),FALSE)-$B10,2)+POWER(VLOOKUP(I$1,'Ral Classic'!$A:$D,COLUMN('Ral Classic'!$C9),FALSE)-$C10,2)+POWER(VLOOKUP(I$1,'Ral Classic'!$A:$D,COLUMN('Ral Classic'!$D9),FALSE)-$D10,2),1/2) -> 87.817994 | J10: =POWER(POWER(VLOOKUP(J$1,'Ral Classic'!$A:$D,COLUMN('Ral Classic'!$B9),FALSE)-$B10,2)+POWER(VLOOKUP(J$1,'Ral Classic'!$A:$D,COLUMN('Ral Classic'!$C9),FALSE)-$C10,2)+POWER(VLOOKUP(J$1,'Ral Classic'!$A:$D,COLUMN('Ral Classic'!$D9),FALSE)-$D10,2),1/2) -> 89.760793 | K10: =POWER(POWER(VLOOKUP(K$1,'Ral Classic'!$A:$D,COLUMN('Ral Classic'!$B9),FALSE)-$B10,2)+POWER(VLOOKUP(K$1,'Ral Classic'!$A:$D,COLUMN('Ral Classic'!$C9),FALSE)-$C10,2)+POWER(VLOOKUP(K$1,'Ral Classic'!$A:$D,COLUMN('Ral Classic'!$D9),FALSE)-$D10,2),1/2) -> 180.025 | L10: =POWER(POWER(VLOOKUP(L$1,'Ral Classic'!$A:$D,COLUMN('Ral Classic'!$B9),FALSE)-$B10,2)+POWER(VLOOKUP(L$1,'Ral Classic'!$A:$D,COLUMN('Ral Classic'!$C9),FALSE)-$C10,2)+POWER(VLOOKUP(L$1,'Ral Classic'!$A:$D,COLUMN('Ral Classic'!$D9),FALSE)-$D10,2),1/2) -> 165.27553 | M10: =POWER(POWER(VLOOKUP(M$1,'Ral Classic'!$A:$D,COLUMN('Ral Classic'!$B9),FALSE)-$B10,2)+POWER(VLOOKUP(M$1,'Ral Classic'!$A:$D,COLUMN('Ral Classic'!$C9),FALSE)-$C10,2)+POWER(VLOOKUP(M$1,'Ral Classic'!$A:$D,COLUMN('Ral Classic'!$D9),FALSE)-$D10,2),1/2) -> 150.21651 | N10: =POWER(POWER(VLOOKUP(N$1,'Ral Classic'!$A:$D,COLUMN('Ral Classic'!$B9),FALSE)-$B10,2)+POWER(VLOOKUP(N$1,'Ral Classic'!$A:$D,COLUMN('Ral Classic'!$C9),FALSE)-$C10,2)+POWER(VLOOKUP(N$1,'Ral Classic'!$A:$D,COLUMN('Ral Classic'!$D9),FALSE)-$D10,2),1/2) -> 162.49308 | O10: =POWER(POWER(VLOOKUP(O$1,'Ral Classic'!$A:$D,COLUMN('Ral Classic'!$B9),FALSE)-$B10,2)+POWER(VLOOKUP(O$1,'Ral Classic'!$A:$D,COLUMN('Ral Classic'!$C9),FALSE)-$C10,2)+POWER(VLOOKUP(O$1,'Ral Classic'!$A:$D,COLUMN('Ral Classic'!$D9),FALSE)-$D10,2),1/2) -> 165.79505 | ... HL10: =POWER(POWER(VLOOKUP(HL$1,'Ral Classic'!$A:$D,COLUMN('Ral Classic'!$B9),FALSE)-$B10,2)+POWER(VLOOKUP(HL$1,'Ral Classic'!$A:$D,COLUMN('Ral Classic'!$C9),FALSE)-$C10,2)+POWER(VLOOKUP(HL$1,'Ral Classic'!$A:$D,COLUMN('Ral Classic'!$D9),FALSE)-$D10,2),1/2) -> 17.378147
A11: 9 | B11: 148 | C11: 148 | D11: 148 | E11: =MIN(H11:HL11) -> 3.7416574 | F11: {=INDEX($1:$1,1,CELL("столбец",INDEX(H11:HL11,MATCH(MIN(H11:HL11),H11:HL11,0))))} -> RAL 7036 | G11: =VLOOKUP(F11,'Ral Classic'!$A:$N,COLUMN('Ral Classic'!$L$1),FALSE) -> Platinum grey | H11: =POWER(POWER(VLOOKUP(H$1,'Ral Classic'!$A:$D,COLUMN('Ral Classic'!$B10),FALSE)-$B11,2)+POWER(VLOOKUP(H$1,'Ral Classic'!$A:$D,COLUMN('Ral Classic'!$C10),FALSE)-$C11,2)+POWER(VLOOKUP(H$1,'Ral Classic'!$A:$D,COLUMN('Ral Classic'!$D10),FALSE)-$D11,2),1/2) -> 69.548544 | I11: =POWER(POWER(VLOOKUP(I$1,'Ral Classic'!$A:$D,COLUMN('Ral Classic'!$B10),FALSE)-$B11,2)+POWER(VLOOKUP(I$1,'Ral Classic'!$A:$D,COLUMN('Ral Classic'!$C10),FALSE)-$C11,2)+POWER(VLOOKUP(I$1,'Ral Classic'!$A:$D,COLUMN('Ral Classic'!$D10),FALSE)-$D11,2),1/2) -> 68.117545 | J11: =POWER(POWER(VLOOKUP(J$1,'Ral Classic'!$A:$D,COLUMN('Ral Classic'!$B10),FALSE)-$B11,2)+POWER(VLOOKUP(J$1,'Ral Classic'!$A:$D,COLUMN('Ral Classic'!$C10),FALSE)-$C11,2)+POWER(VLOOKUP(J$1,'Ral Classic'!$A:$D,COLUMN('Ral Classic'!$D10),FALSE)-$D11,2),1/2) -> 76.478755 | K11: =POWER(POWER(VLOOKUP(K$1,'Ral Classic'!$A:$D,COLUMN('Ral Classic'!$B10),FALSE)-$B11,2)+POWER(VLOOKUP(K$1,'Ral Classic'!$A:$D,COLUMN('Ral Classic'!$C10),FALSE)-$C11,2)+POWER(VLOOKUP(K$1,'Ral Classic'!$A:$D,COLUMN('Ral Classic'!$D10),FALSE)-$D11,2),1/2) -> 180.29143 | L11: =POWER(POWER(VLOOKUP(L$1,'Ral Classic'!$A:$D,COLUMN('Ral Classic'!$B10),FALSE)-$B11,2)+POWER(VLOOKUP(L$1,'Ral Classic'!$A:$D,COLUMN('Ral Classic'!$C10),FALSE)-$C11,2)+POWER(VLOOKUP(L$1,'Ral Classic'!$A:$D,COLUMN('Ral Classic'!$D10),FALSE)-$D11,2),1/2) -> 168.53486 | M11: =POWER(POWER(VLOOKUP(M$1,'Ral Classic'!$A:$D,COLUMN('Ral Classic'!$B10),FALSE)-$B11,2)+POWER(VLOOKUP(M$1,'Ral Classic'!$A:$D,COLUMN('Ral Classic'!$C10),FALSE)-$C11,2)+POWER(VLOOKUP(M$1,'Ral Classic'!$A:$D,COLUMN('Ral Classic'!$D10),FALSE)-$D11,2),1/2) -> 158.00316 | N11: =POWER(POWER(VLOOKUP(N$1,'Ral Classic'!$A:$D,COLUMN('Ral Classic'!$B10),FALSE)-$B11,2)+POWER(VLOOKUP(N$1,'Ral Classic'!$A:$D,COLUMN('Ral Classic'!$C10),FALSE)-$C11,2)+POWER(VLOOKUP(N$1,'Ral Classic'!$A:$D,COLUMN('Ral Classic'!$D10),FALSE)-$D11,2),1/2) -> 167.34396 | O11: =POWER(POWER(VLOOKUP(O$1,'Ral Classic'!$A:$D,COLUMN('Ral Classic'!$B10),FALSE)-$B11,2)+POWER(VLOOKUP(O$1,'Ral Classic'!$A:$D,COLUMN('Ral Classic'!$C10),FALSE)-$C11,2)+POWER(VLOOKUP(O$1,'Ral Classic'!$A:$D,COLUMN('Ral Classic'!$D10),FALSE)-$D11,2),1/2) -> 170.36432 | ... HL11: =POWER(POWER(VLOOKUP(HL$1,'Ral Classic'!$A:$D,COLUMN('Ral Classic'!$B10),FALSE)-$B11,2)+POWER(VLOOKUP(HL$1,'Ral Classic'!$A:$D,COLUMN('Ral Classic'!$C10),FALSE)-$C11,2)+POWER(VLOOKUP(HL$1,'Ral Classic'!$A:$D,COLUMN('Ral Classic'!$D10),FALSE)-$D11,2),1/2) -> 45.055521
A12: 10 | B12: 168 | C12: 168 | D12: 168 | E12: =MIN(H12:HL12) -> 11.445523 | F12: {=INDEX($1:$1,1,CELL("столбец",INDEX(H12:HL12,MATCH(MIN(H12:HL12),H12:HL12,0))))} -> RAL 7038 | G12: =VLOOKUP(F12,'Ral Classic'!$A:$N,COLUMN('Ral Classic'!$L$1),FALSE) -> Agate grey | H12: =POWER(POWER(VLOOKUP(H$1,'Ral Classic'!$A:$D,COLUMN('Ral Classic'!$B11),FALSE)-$B12,2)+POWER(VLOOKUP(H$1,'Ral Classic'!$A:$D,COLUMN('Ral Classic'!$C11),FALSE)-$C12,2)+POWER(VLOOKUP(H$1,'Ral Classic'!$A:$D,COLUMN('Ral Classic'!$D11),FALSE)-$D12,2),1/2) -> 52.12485 | I12: =POWER(POWER(VLOOKUP(I$1,'Ral Classic'!$A:$D,COLUMN('Ral Classic'!$B11),FALSE)-$B12,2)+POWER(VLOOKUP(I$1,'Ral Classic'!$A:$D,COLUMN('Ral Classic'!$C11),FALSE)-$C12,2)+POWER(VLOOKUP(I$1,'Ral Classic'!$A:$D,COLUMN('Ral Classic'!$D11),FALSE)-$D12,2),1/2) -> 54.405882 | J12: =POWER(POWER(VLOOKUP(J$1,'Ral Classic'!$A:$D,COLUMN('Ral Classic'!$B11),FALSE)-$B12,2)+POWER(VLOOKUP(J$1,'Ral Classic'!$A:$D,COLUMN('Ral Classic'!$C11),FALSE)-$C12,2)+POWER(VLOOKUP(J$1,'Ral Classic'!$A:$D,COLUMN('Ral Classic'!$D11),FALSE)-$D12,2),1/2) -> 72.449983 | K12: =POWER(POWER(VLOOKUP(K$1,'Ral Classic'!$A:$D,COLUMN('Ral Classic'!$B11),FALSE)-$B12,2)+POWER(VLOOKUP(K$1,'Ral Classic'!$A:$D,COLUMN('Ral Classic'!$C11),FALSE)-$C12,2)+POWER(VLOOKUP(K$1,'Ral Classic'!$A:$D,COLUMN('Ral Classic'!$D11),FALSE)-$D12,2),1/2) -> 186.50737 | L12: =POWER(POWER(VLOOKUP(L$1,'Ral Classic'!$A:$D,COLUMN('Ral Classic'!$B11),FALSE)-$B12,2)+POWER(VLOOKUP(L$1,'Ral Classic'!$A:$D,COLUMN('Ral Classic'!$C11),FALSE)-$C12,2)+POWER(VLOOKUP(L$1,'Ral Classic'!$A:$D,COLUMN('Ral Classic'!$D11),FALSE)-$D12,2),1/2) -> 178.67289 | M12: =POWER(POWER(VLOOKUP(M$1,'Ral Classic'!$A:$D,COLUMN('Ral Classic'!$B11),FALSE)-$B12,2)+POWER(VLOOKUP(M$1,'Ral Classic'!$A:$D,COLUMN('Ral Classic'!$C11),FALSE)-$C12,2)+POWER(VLOOKUP(M$1,'Ral Classic'!$A:$D,COLUMN('Ral Classic'!$D11),FALSE)-$D12,2),1/2) -> 173.56555 | N12: =POWER(POWER(VLOOKUP(N$1,'Ral Classic'!$A:$D,COLUMN('Ral Classic'!$B11),FALSE)-$B12,2)+POWER(VLOOKUP(N$1,'Ral Classic'!$A:$D,COLUMN('Ral Classic'!$C11),FALSE)-$C12,2)+POWER(VLOOKUP(N$1,'Ral Classic'!$A:$D,COLUMN('Ral Classic'!$D11),FALSE)-$D12,2),1/2) -> 179.34325 | O12: =POWER(POWER(VLOOKUP(O$1,'Ral Classic'!$A:$D,COLUMN('Ral Classic'!$B11),FALSE)-$B12,2)+POWER(VLOOKUP(O$1,'Ral Classic'!$A:$D,COLUMN('Ral Classic'!$C11),FALSE)-$C12,2)+POWER(VLOOKUP(O$1,'Ral Classic'!$A:$D,COLUMN('Ral Classic'!$D11),FALSE)-$D12,2),1/2) -> 181.94505 | ... HL12: =POWER(POWER(VLOOKUP(HL$1,'Ral Classic'!$A:$D,COLUMN('Ral Classic'!$B11),FALSE)-$B12,2)+POWER(VLOOKUP(HL$1,'Ral Classic'!$A:$D,COLUMN('Ral Classic'!$C11),FALSE)-$C12,2)+POWER(VLOOKUP(HL$1,'Ral Classic'!$A:$D,COLUMN('Ral Classic'!$D11),FALSE)-$D12,2),1/2) -> 79.686887
A13: 11 | B13: 184 | C13: 184 | D13: 184 | E13: =MIN(H13:HL13) -> 16.881943 | F13: {=INDEX($1:$1,1,CELL("столбец",INDEX(H13:HL13,MATCH(MIN(H13:HL13),H13:HL13,0))))} -> RAL 7044 | G13: =VLOOKUP(F13,'Ral Classic'!$A:$N,COLUMN('Ral Classic'!$L$1),FALSE) -> Silk grey | H13: =POWER(POWER(VLOOKUP(H$1,'Ral Classic'!$A:$D,COLUMN('Ral Classic'!$B12),FALSE)-$B13,2)+POWER(VLOOKUP(H$1,'Ral Classic'!$A:$D,COLUMN('Ral Classic'!$C12),FALSE)-$C13,2)+POWER(VLOOKUP(H$1,'Ral Classic'!$A:$D,COLUMN('Ral Classic'!$D12),FALSE)-$D13,2),1/2) -> 52.430907 | I13: =POWER(POWER(VLOOKUP(I$1,'Ral Classic'!$A:$D,COLUMN('Ral Classic'!$B12),FALSE)-$B13,2)+POWER(VLOOKUP(I$1,'Ral Classic'!$A:$D,COLUMN('Ral Classic'!$C12),FALSE)-$C13,2)+POWER(VLOOKUP(I$1,'Ral Classic'!$A:$D,COLUMN('Ral Classic'!$D12),FALSE)-$D13,2),1/2) -> 57.827329 | J13: =POWER(POWER(VLOOKUP(J$1,'Ral Classic'!$A:$D,COLUMN('Ral Classic'!$B12),FALSE)-$B13,2)+POWER(VLOOKUP(J$1,'Ral Classic'!$A:$D,COLUMN('Ral Classic'!$C12),FALSE)-$C13,2)+POWER(VLOOKUP(J$1,'Ral Classic'!$A:$D,COLUMN('Ral Classic'!$D12),FALSE)-$D13,2),1/2) -> 80.60397 | K13: =POWER(POWER(VLOOKUP(K$1,'Ral Classic'!$A:$D,COLUMN('Ral Classic'!$B12),FALSE)-$B13,2)+POWER(VLOOKUP(K$1,'Ral Classic'!$A:$D,COLUMN('Ral Classic'!$C12),FALSE)-$C13,2)+POWER(VLOOKUP(K$1,'Ral Classic'!$A:$D,COLUMN('Ral Classic'!$D12),FALSE)-$D13,2),1/2) -> 195.79837 | L13: =POWER(POWER(VLOOKUP(L$1,'Ral Classic'!$A:$D,COLUMN('Ral Classic'!$B12),FALSE)-$B13,2)+POWER(VLOOKUP(L$1,'Ral Classic'!$A:$D,COLUMN('Ral Classic'!$C12),FALSE)-$C13,2)+POWER(VLOOKUP(L$1,'Ral Classic'!$A:$D,COLUMN('Ral Classic'!$D12),FALSE)-$D13,2),1/2) -> 190.96597 | M13: =POWER(POWER(VLOOKUP(M$1,'Ral Classic'!$A:$D,COLUMN('Ral Classic'!$B12),FALSE)-$B13,2)+POWER(VLOOKUP(M$1,'Ral Classic'!$A:$D,COLUMN('Ral Classic'!$C12),FALSE)-$C13,2)+POWER(VLOOKUP(M$1,'Ral Classic'!$A:$D,COLUMN('Ral Classic'!$D12),FALSE)-$D13,2),1/2) -> 189.68658 | N13: =POWER(POWER(VLOOKUP(N$1,'Ral Classic'!$A:$D,COLUMN('Ral Classic'!$B12),FALSE)-$B13,2)+POWER(VLOOKUP(N$1,'Ral Classic'!$A:$D,COLUMN('Ral Classic'!$C12),FALSE)-$C13,2)+POWER(VLOOKUP(N$1,'Ral Classic'!$A:$D,COLUMN('Ral Classic'!$D12),FALSE)-$D13,2),1/2) -> 192.92486 | O13: =POWER(POWER(VLOOKUP(O$1,'Ral Classic'!$A:$D,COLUMN('Ral Classic'!$B12),FALSE)-$B13,2)+POWER(VLOOKUP(O$1,'Ral Classic'!$A:$D,COLUMN('Ral Classic'!$C12),FALSE)-$C13,2)+POWER(VLOOKUP(O$1,'Ral Classic'!$A:$D,COLUMN('Ral Classic'!$D12),FALSE)-$D13,2),1/2) -> 195.18197 | ... HL13: =POWER(POWER(VLOOKUP(HL$1,'Ral Classic'!$A:$D,COLUMN('Ral Classic'!$B12),FALSE)-$B13,2)+POWER(VLOOKUP(HL$1,'Ral Classic'!$A:$D,COLUMN('Ral Classic'!$C12),FALSE)-$C13,2)+POWER(VLOOKUP(HL$1,'Ral Classic'!$A:$D,COLUMN('Ral Classic'!$D12),FALSE)-$D13,2),1/2) -> 107.39646
... A216: 214 | B216: 88 | C216: 152 | D216: 172 | E216: =MIN(H216:HL216) -> 16.155494 | F216: {=INDEX($1:$1,1,CELL("столбец",INDEX(H216:HL216,MATCH(MIN(H216:HL216),H216:HL216,0))))} -> RAL 5024 | G216: =VLOOKUP(F216,'Ral Classic'!$A:$N,COLUMN('Ral Classic'!$L$1),FALSE) -> Pastel blue | H216: =POWER(POWER(VLOOKUP(H$1,'Ral Classic'!$A:$D,COLUMN('Ral Classic'!$B215),FALSE)-$B216,2)+POWER(VLOOKUP(H$1,'Ral Classic'!$A:$D,COLUMN('Ral Classic'!$C215),FALSE)-$C216,2)+POWER(VLOOKUP(H$1,'Ral Classic'!$A:$D,COLUMN('Ral Classic'!$D215),FALSE)-$D216,2),1/2) -> 127.04724 | I216: =POWER(POWER(VLOOKUP(I$1,'Ral Classic'!$A:$D,COLUMN('Ral Classic'!$B215),FALSE)-$B216,2)+POWER(VLOOKUP(I$1,'Ral Classic'!$A:$D,COLUMN('Ral Classic'!$C215),FALSE)-$C216,2)+POWER(VLOOKUP(I$1,'Ral Classic'!$A:$D,COLUMN('Ral Classic'!$D215),FALSE)-$D216,2),1/2) -> 128.74782 | J216: =POWER(POWER(VLOOKUP(J$1,'Ral Classic'!$A:$D,COLUMN('Ral Classic'!$B215),FALSE)-$B216,2)+POWER(VLOOKUP(J$1,'Ral Classic'!$A:$D,COLUMN('Ral Classic'!$C215),FALSE)-$C216,2)+POWER(VLOOKUP(J$1,'Ral Classic'!$A:$D,COLUMN('Ral Classic'!$D215),FALSE)-$D216,2),1/2) -> 138.48105 | K216: =POWER(POWER(VLOOKUP(K$1,'Ral Classic'!$A:$D,COLUMN('Ral Classic'!$B215),FALSE)-$B216,2)+POWER(VLOOKUP(K$1,'Ral Classic'!$A:$D,COLUMN('Ral Classic'!$C215),FALSE)-$C216,2)+POWER(VLOOKUP(K$1,'Ral Classic'!$A:$D,COLUMN('Ral Classic'!$D215),FALSE)-$D216,2),1/2) -> 236.13767 | L216: =POWER(POWER(VLOOKUP(L$1,'Ral Classic'!$A:$D,COLUMN('Ral Classic'!$B215),FALSE)-$B216,2)+POWER(VLOOKUP(L$1,'Ral Classic'!$A:$D,COLUMN('Ral Classic'!$C215),FALSE)-$C216,2)+POWER(VLOOKUP(L$1,'Ral Classic'!$A:$D,COLUMN('Ral Classic'!$D215),FALSE)-$D216,2),1/2) -> 221.85581 | M216: =POWER(POWER(VLOOKUP(M$1,'Ral Classic'!$A:$D,COLUMN('Ral Classic'!$B215),FALSE)-$B216,2)+POWER(VLOOKUP(M$1,'Ral Classic'!$A:$D,COLUMN('Ral Classic'!$C215),FALSE)-$C216,2)+POWER(VLOOKUP(M$1,'Ral Classic'!$A:$D,COLUMN('Ral Classic'!$D215),FALSE)-$D216,2),1/2) -> 207.14488 | N216: =POWER(POWER(VLOOKUP(N$1,'Ral Classic'!$A:$D,COLUMN('Ral Classic'!$B215),FALSE)-$B216,2)+POWER(VLOOKUP(N$1,'Ral Classic'!$A:$D,COLUMN('Ral Classic'!$C215),FALSE)-$C216,2)+POWER(VLOOKUP(N$1,'Ral Classic'!$A:$D,COLUMN('Ral Classic'!$D215),FALSE)-$D216,2),1/2) -> 220.66264 | O216: =POWER(POWER(VLOOKUP(O$1,'Ral Classic'!$A:$D,COLUMN('Ral Classic'!$B215),FALSE)-$B216,2)+POWER(VLOOKUP(O$1,'Ral Classic'!$A:$D,COLUMN('Ral Classic'!$C215),FALSE)-$C216,2)+POWER(VLOOKUP(O$1,'Ral Classic'!$A:$D,COLUMN('Ral Classic'!$D215),FALSE)-$D216,2),1/2) -> 224.64194 | ... HL216: =POWER(POWER(VLOOKUP(HL$1,'Ral Classic'!$A:$D,COLUMN('Ral Classic'!$B215),FALSE)-$B216,2)+POWER(VLOOKUP(HL$1,'Ral Classic'!$A:$D,COLUMN('Ral Classic'!$C215),FALSE)-$C216,2)+POWER(VLOOKUP(HL$1,'Ral Classic'!$A:$D,COLUMN('Ral Classic'!$D215),FALSE)-$D216,2),1/2) -> 66.558245
G217: Min | H217: =MIN(H1:H216) -> 10.816654 | I217: =MIN(I1:I216) -> 13.266499 | J217: =MIN(J1:J216) -> 22.293497 | K217: =MIN(K1:K216) -> 5 | L217: =MIN(L1:L216) -> 14.56022 | M217: =MIN(M1:M216) -> 10.049876 | N217: =MIN(N1:N216) -> 4.472136 | O217: =MIN(O1:O216) -> 6.9282032 | ... HL217: =MIN(HL1:HL216) -> 10.488088
G218: at line | H218: =MATCH(MIN(H1:H216),H1:H216,0) -> 61 | I218: =MATCH(MIN(I1:I216),I1:I216,0) -> 61 | J218: =MATCH(MIN(J1:J216),J1:J216,0) -> 121 | K218: =MATCH(MIN(K1:K216),K1:K216,0) -> 190 | L218: =MATCH(MIN(L1:L216),L1:L216,0) -> 195 | M218: =MATCH(MIN(M1:M216),M1:M216,0) -> 194 | N218: =MATCH(MIN(N1:N216),N1:N216,0) -> 195 | O218: =MATCH(MIN(O1:O216),O1:O216,0) -> 195 | ... HL218: =MATCH(MIN(HL1:HL216),HL1:HL216,0) -> 9
G219: Num | H219: {=INDEX($A1:$A216,H218,1)} -> 59 | I219: {=INDEX($A1:$A216,I218,1)} -> 59 | J219: {=INDEX($A1:$A216,J218,1)} -> 119 | K219: {=INDEX($A1:$A216,K218,1)} -> 188 | L219: {=INDEX($A1:$A216,L218,1)} -> 193 | M219: {=INDEX($A1:$A216,M218,1)} -> 192 | N219: {=INDEX($A1:$A216,N218,1)} -> 193 | O219: {=INDEX($A1:$A216,O218,1)} -> 193 | ... HL219: {=INDEX($A1:$A216,HL218,1)} -> 7

Sheet Ral Classic
A1: RAL number | B1: ='TTD-DOS'!B1 -> R | C1: ='TTD-DOS'!C1 -> G | D1: ='TTD-DOS'!D1 -> B | E1: min | F1: TTD | G1: HEX | H1: ='TTD-DOS'!B1 -> R | I1: ='TTD-DOS'!C1 -> G | J1: ='TTD-DOS'!D1 -> B | K1: =A1 -> RAL number | L1: English | M1: German | N1: Russian | O1: Bulgarian
A2: RAL 1000 | B2: 205 | C2: 186 | D2: 136 | E2: =HLOOKUP(A2,'TTD-DOS'!$1:$217,ROW('TTD-DOS'!$H$217),FALSE) -> 10.816654 | F2: =HLOOKUP(A2,'TTD-DOS'!$1:$219,ROW('TTD-DOS'!$H$219),FALSE) -> 59 | G2: =DEC2HEX(F2,2) -> 3B | H2: =VLOOKUP($F2,'TTD-DOS'!$A:$D,COLUMN('TTD-DOS'!B$1),FALSE) -> 196 | I2: =VLOOKUP($F2,'TTD-DOS'!$A:$D,COLUMN('TTD-DOS'!C$1),FALSE) -> 180 | J2: =VLOOKUP($F2,'TTD-DOS'!$A:$D,COLUMN('TTD-DOS'!D$1),FALSE) -> 136 | K2: =A2 -> RAL 1000 | L2: Green beige | M2: Grünbeige | N2: Зелёно-бежевый | O2: зелено-бежов
A3: RAL 1001 | B3: 208 | C3: 176 | D3: 132 | E3: =HLOOKUP(A3,'TTD-DOS'!$1:$217,ROW('TTD-DOS'!$H$217),FALSE) -> 13.266499 | F3: =HLOOKUP(A3,'TTD-DOS'!$1:$219,ROW('TTD-DOS'!$H$219),FALSE) -> 59 | G3: =DEC2HEX(F3,2) -> 3B | H3: =VLOOKUP($F3,'TTD-DOS'!$A:$D,COLUMN('TTD-DOS'!B$1),FALSE) -> 196 | I3: =VLOOKUP($F3,'TTD-DOS'!$A:$D,COLUMN('TTD-DOS'!C$1),FALSE) -> 180 | J3: =VLOOKUP($F3,'TTD-DOS'!$A:$D,COLUMN('TTD-DOS'!D$1),FALSE) -> 136 | K3: =A3 -> RAL 1001 | L3: Beige | M3: Beige | N3: Бежевый | O3: бежов
A4: RAL 1002 | B4: 210 | C4: 170 | D4: 109 | E4: =HLOOKUP(A4,'TTD-DOS'!$1:$217,ROW('TTD-DOS'!$H$217),FALSE) -> 22.293497 | F4: =HLOOKUP(A4,'TTD-DOS'!$1:$219,ROW('TTD-DOS'!$H$219),FALSE) -> 119 | G4: =DEC2HEX(F4,2) -> 77 | H4: =VLOOKUP($F4,'TTD-DOS'!$A:$D,COLUMN('TTD-DOS'!B$1),FALSE) -> 212 | I4: =VLOOKUP($F4,'TTD-DOS'!$A:$D,COLUMN('TTD-DOS'!C$1),FALSE) -> 148 | J4: =VLOOKUP($F4,'TTD-DOS'!$A:$D,COLUMN('TTD-DOS'!D$1),FALSE) -> 112 | K4: =A4 -> RAL 1002 | L4: Sand yellow | M4: Sandgelb | N4: Песочно-жёлтый | O4: пясъчно жълто
A5: RAL 1003 | B5: 249 | C5: 168 | D5: 0 | E5: =HLOOKUP(A5,'TTD-DOS'!$1:$217,ROW('TTD-DOS'!$H$217),FALSE) -> 5 | F5: =HLOOKUP(A5,'TTD-DOS'!$1:$219,ROW('TTD-DOS'!$H$219),FALSE) -> 188 | G5: =DEC2HEX(F5,2) -> BC | H5: =VLOOKUP($F5,'TTD-DOS'!$A:$D,COLUMN('TTD-DOS'!B$1),FALSE) -> 252 | I5: =VLOOKUP($F5,'TTD-DOS'!$A:$D,COLUMN('TTD-DOS'!C$1),FALSE) -> 164 | J5: =VLOOKUP($F5,'TTD-DOS'!$A:$D,COLUMN('TTD-DOS'!D$1),FALSE) -> 0 | K5: =A5 -> RAL 1003 | L5: Signal yellow | M5: Signalgelb | N5: Сигнальный жёлтый | O5: сигнално жълто
A6: RAL 1004 | B6: 228 | C6: 158 | D6: 0 | E6: =HLOOKUP(A6,'TTD-DOS'!$1:$217,ROW('TTD-DOS'!$H$217),FALSE) -> 14.56022 | F6: =HLOOKUP(A6,'TTD-DOS'!$1:$219,ROW('TTD-DOS'!$H$219),FALSE) -> 193 | G6: =DEC2HEX(F6,2) -> C1 | H6: =VLOOKUP($F6,'TTD-DOS'!$A:$D,COLUMN('TTD-DOS'!B$1),FALSE) -> 228 | I6: =VLOOKUP($F6,'TTD-DOS'!$A:$D,COLUMN('TTD-DOS'!C$1),FALSE) -> 144 | J6: =VLOOKUP($F6,'TTD-DOS'!$A:$D,COLUMN('TTD-DOS'!D$1),FALSE) -> 4 | K6: =A6 -> RAL 1004 | L6: Golden yellow | M6: Goldgelb | N6: Золотисто-жёлтый | O6: златно жълто
A7: RAL 1005 | B7: 203 | C7: 142 | D7: 0 | E7: =HLOOKUP(A7,'TTD-DOS'!$1:$217,ROW('TTD-DOS'!$H$217),FALSE) -> 10.049876 | F7: =HLOOKUP(A7,'TTD-DOS'!$1:$219,ROW('TTD-DOS'!$H$219),FALSE) -> 192 | G7: =DEC2HEX(F7,2) -> C0 | H7: =VLOOKUP($F7,'TTD-DOS'!$A:$D,COLUMN('TTD-DOS'!B$1),FALSE) -> 204 | I7: =VLOOKUP($F7,'TTD-DOS'!$A:$D,COLUMN('TTD-DOS'!C$1),FALSE) -> 136 | J7: =VLOOKUP($F7,'TTD-DOS'!$A:$D,COLUMN('TTD-DOS'!D$1),FALSE) -> 8 | K7: =A7 -> RAL 1005 | L7: Honey yellow | M7: Honiggelb | N7: Медово-жёлтый | O7: медено жълто
A8: RAL 1006 | B8: 226 | C8: 144 | D8: 0 | E8: =HLOOKUP(A8,'TTD-DOS'!$1:$217,ROW('TTD-DOS'!$H$217),FALSE) -> 4.472136 | F8: =HLOOKUP(A8,'TTD-DOS'!$1:$219,ROW('TTD-DOS'!$H$219),FALSE) -> 193 | G8: =DEC2HEX(F8,2) -> C1 | H8: =VLOOKUP($F8,'TTD-DOS'!$A:$D,COLUMN('TTD-DOS'!B$1),FALSE) -> 228 | I8: =VLOOKUP($F8,'TTD-DOS'!$A:$D,COLUMN('TTD-DOS'!C$1),FALSE) -> 144 | J8: =VLOOKUP($F8,'TTD-DOS'!$A:$D,COLUMN('TTD-DOS'!D$1),FALSE) -> 4 | K8: =A8 -> RAL 1006 | L8: Maize yellow | M8: Maisgelb | N8: Кукурузно-жёлтый | O8: царевично жълто
A9: RAL 1007 | B9: 232 | C9: 140 | D9: 0 | E9: =HLOOKUP(A9,'TTD-DOS'!$1:$217,ROW('TTD-DOS'!$H$217),FALSE) -> 6.9282032 | F9: =HLOOKUP(A9,'TTD-DOS'!$1:$219,ROW('TTD-DOS'!$H$219),FALSE) -> 193 | G9: =DEC2HEX(F9,2) -> C1 | H9: =VLOOKUP($F9,'TTD-DOS'!$A:$D,COLUMN('TTD-DOS'!B$1),FALSE) -> 228 | I9: =VLOOKUP($F9,'TTD-DOS'!$A:$D,COLUMN('TTD-DOS'!C$1),FALSE) -> 144 | J9: =VLOOKUP($F9,'TTD-DOS'!$A:$D,COLUMN('TTD-DOS'!D$1),FALSE) -> 4 | K9: =A9 -> RAL 1007 | L9: Daffodil yellow | M9: Narzissengelb | N9: Жёлтый нарцисс | O9: нарцисово жълто
A10: RAL 1011 | B10: 175 | C10: 128 | D10: 79 | E10: =HLOOKUP(A10,'TTD-DOS'!$1:$217,ROW('TTD-DOS'!$H$217),FALSE) -> 17.492856 | F10: =HLOOKUP(A10,'TTD-DOS'!$1:$219,ROW('TTD-DOS'!$H$219),FALSE) -> 111 | G10: =DEC2HEX(F10,2) -> 6F | H10: =VLOOKUP($F10,'TTD-DOS'!$A:$D,COLUMN('TTD-DOS'!B$1),FALSE) -> 160 | I10: =VLOOKUP($F10,'TTD-DOS'!$A:$D,COLUMN('TTD-DOS'!C$1),FALSE) -> 128 | J10: =VLOOKUP($F10,'TTD-DOS'!$A:$D,COLUMN('TTD-DOS'!D$1),FALSE) -> 88 | K10: =A10 -> RAL 1011 | L10: Brown beige | M10: Braunbeige | N10: Коричнево-бежевый | O10: кафяво-бежов
A11: RAL 1012 | B11: 221 | C11: 175 | D11: 39 | E11: =HLOOKUP(A11,'TTD-DOS'!$1:$217,ROW('TTD-DOS'!$H$217),FALSE) -> 22.15852 | F11: =HLOOKUP(A11,'TTD-DOS'!$1:$219,ROW('TTD-DOS'!$H$219),FALSE) -> 65 | G11: =DEC2HEX(F11,2) -> 41 | H11: =VLOOKUP($F11,'TTD-DOS'!$A:$D,COLUMN('TTD-DOS'!B$1),FALSE) -> 212 | I11: =VLOOKUP($F11,'TTD-DOS'!$A:$D,COLUMN('TTD-DOS'!C$1),FALSE) -> 156 | J11: =VLOOKUP($F11,'TTD-DOS'!$A:$D,COLUMN('TTD-DOS'!D$1),FALSE) -> 32 | K11: =A11 -> RAL 1012 | L11: Lemon yellow | M11: Zitronengelb | N11: Лимонно-жёлтый | O11: лимоново жълто
A12: RAL 1013 | B12: 227 | C12: 217 | D12: 198 | E12: =HLOOKUP(A12,'TTD-DOS'!$1:$217,ROW('TTD-DOS'!$H$217),FALSE) -> 21.118712 | F12: =HLOOKUP(A12,'TTD-DOS'!$1:$219,ROW('TTD-DOS'!$H$219),FALSE) -> 13 | G12: =DEC2HEX(F12,2) -> 0D | H12: =VLOOKUP($F12,'TTD-DOS'!$A:$D,COLUMN('TTD-DOS'!B$1),FALSE) -> 216 | I12: =VLOOKUP($F12,'TTD-DOS'!$A:$D,COLUMN('TTD-DOS'!C$1),FALSE) -> 216 | J12: =VLOOKUP($F12,'TTD-DOS'!$A:$D,COLUMN('TTD-DOS'!D$1),FALSE) -> 216 | K12: =A12 -> RAL 1013 | L12: Oyster white | M12: Perlweiß | N12: Жемчужно-белый | O12: перлено бяло
A13: RAL 1014 | B13: 221 | C13: 196 | D13: 154 | E13: =HLOOKUP(A13,'TTD-DOS'!$1:$217,ROW('TTD-DOS'!$H$217),FALSE) -> 13.453624 | F13: =HLOOKUP(A13,'TTD-DOS'!$1:$219,ROW('TTD-DOS'!$H$219),FALSE) -> 38 | G13: =DEC2HEX(F13,2) -> 26 | H13: =VLOOKUP($F13,'TTD-DOS'!$A:$D,COLUMN('TTD-DOS'!B$1),FALSE) -> 212 | I13: =VLOOKUP($F13,'TTD-DOS'!$A:$D,COLUMN('TTD-DOS'!C$1),FALSE) -> 188 | J13: =VLOOKUP($F13,'TTD-DOS'!$A:$D,COLUMN('TTD-DOS'!D$1),FALSE) -> 148 | K13: =A13 -> RAL 1014 | L13: Ivory | M13: Elfenbein | N13: Слоновая кость | O13: слонова кост
... A214: RAL 9023 | B214: 121 | C214: 123 | D214: 122 | E214: =HLOOKUP(A214,'TTD-DOS'!$1:$217,ROW('TTD-DOS'!$H$217),FALSE) -> 10.488088 | F214: =HLOOKUP(A214,'TTD-DOS'!$1:$219,ROW('TTD-DOS'!$H$219),FALSE) -> 7 | G214: =DEC2HEX(F214,2) -> 07 | H214: =VLOOKUP($F214,'TTD-DOS'!$A:$D,COLUMN('TTD-DOS'!B$1),FALSE) -> 116 | I214: =VLOOKUP($F214,'TTD-DOS'!$A:$D,COLUMN('TTD-DOS'!C$1),FALSE) -> 116 | J214: =VLOOKUP($F214,'TTD-DOS'!$A:$D,COLUMN('TTD-DOS'!D$1),FALSE) -> 116 | K214: =A214 -> RAL 9023 | L214: Pearl dark grey | M214: Perldunkelgrau | N214: Жемчужный тёмно-серый | O214: перлено тъмносиво

Sheet RAL Classic Bulgarian
A1: RAL код | B1: Наименование на цвета
A2: Жълти
A3: 1000 | B3: зелено-бежов
A4: 1001 | B4: бежов
A5: 1002 | B5: пясъчно жълто
A6: 1003 | B6: сигнално жълто
A7: 1004 | B7: златно жълто
A8: 1005 | B8: медено жълто
A9: 1006 | B9: царевично жълто
A10: 1007 | B10: нарцисово жълто
A11: 1011 | B11: кафяво-бежов
A12: 1012 | B12: лимоново жълто
A13: 1013 | B13: перлено бяло
A14: 1014 | B14: слонова кост
... A32: 1037 | B32: слънчево жълто
A33: Оранжеви
A34: 2000 | B34: жълто-оранжево
A35: 2001 | B35: червено-оранжево
A36: 2002 | B36: кърваво оранжево
A37: 2003 | B37: пастелно оранжево
A38: 2004 | B38: чисто оранжево
A39: 2005 | B39: лъчисто оранжево
A40: 2007 | B40: светло лъчисто оранжево
A41: 2008 | B41: светло червено-оранжево
A42: 2009 | B42: транспортно оранжево
A43: 2010 | B43: сигнално оранжево
A44: 2011 | B44: дълбоко оранжево
A45: 2012 | B45: сьомгово оранжево
A46: 2013 | B46: перлено оранжево
A47: Червени
A48: 3000 | B48: огнено червено
A49: 3001 | B49: сигнално червено
A50: 3002 | B50: карминово червено
A51: 3003 | B51: рубинено червено
A52: 3004 | B52: пурпурно червено
A53: 3005 | B53: виненочервено
A54: 3007 | B54: тъмночервено
A55: 3009 | B55: окисово червено
A56: 3011 | B56: кафяво-червено
A57: 3012 | B57: бежово-червено
...

Sheet Ral Design
A1: ='TTD-DOS'!B1 -> R | B1: ='TTD-DOS'!C1 -> G | C1: ='TTD-DOS'!D1 -> B | D1: Code | E1: Name
A2: 33 | B2: 33 | C2: 34 | D2: H000L15C00 | E2: Ink Black
A3: 43 | B3: 43 | C3: 43 | D3: H000L20C00 | E3: Slate Black
A4: 58 | B4: 58 | C4: 58 | D4: H000L25C00 | E4: Onyx Black
A5: 68 | B5: 68 | C5: 67 | D5: H000L30C00 | E5: Medium Black
A6: 80 | B6: 80 | C6: 80 | D6: H000L35C00 | E6: Briquette Grey
A7: 93 | B7: 92 | C7: 91 | D7: H000L40C00 | E7: Dark Grey
A8: 107 | B8: 106 | C8: 105 | D8: H000L45C00 | E8: Architecture Grey
A9: 118 | B9: 118 | C9: 117 | D9: H000L50C00 | E9: Steel Grey
A10: 130 | B10: 130 | C10: 130 | D10: H000L55C00 | E10: Medium Grey
A11: 143 | B11: 143 | C11: 142 | D11: H000L60C00 | E11: Ash Grey
A12: 158 | B12: 159 | C12: 158 | D12: H000L65C00 | E12: Mortar Grey
A13: 172 | B13: 173 | C13: 172 | D13: H000L70C00 | E13: Light Grey
... A1826: 249 | B1826: 234 | C1826: 235 | D1826: H360L93C05 | E1826: Arrowhead White

Sheet ChatGPT
A1: 1 | B1: 16 | C1: 16 | D1: 16 | E1: RAL 9005 | F1: Jet black | G1: =HLOOKUP(E1,'TTD-DOS'!$1:$218,A1+2,FALSE) -> 2.8284271
A2: 2 | B2: 32 | C2: 32 | D2: 32 | E2: RAL 5004 | F2: Black blue | G2: =HLOOKUP(E2,'TTD-DOS'!$1:$218,A2+2,FALSE) -> 10.198039
A3: 3 | B3: 48 | C3: 48 | D3: 48 | E3: RAL 7021 | F3: Black grey | G3: =HLOOKUP(E3,'TTD-DOS'!$1:$218,A3+2,FALSE) -> 4.472136
A4: 4 | B4: 64 | C4: 64 | D4: 64 | E4: RAL 7016 | F4: Anthracite grey | G4: =HLOOKUP(E4,'TTD-DOS'!$1:$218,A4+2,FALSE) -> 8.4852814
A5: 5 | B5: 80 | C5: 80 | D5: 80 | E5: RAL 7043 | F5: Traffic grey B | G5: =HLOOKUP(E5,'TTD-DOS'!$1:$218,A5+2,FALSE) -> 2.236068
A6: 6 | B6: 100 | C6: 100 | D6: 100 | E6: RAL 7039 | F6: Quartz grey | G6: =HLOOKUP(E6,'TTD-DOS'!$1:$218,A6+2,FALSE) -> 8.7177979
A7: 7 | B7: 116 | C7: 116 | D7: 116 | E7: RAL 9023 | F7: Pearl dark grey | G7: =HLOOKUP(E7,'TTD-DOS'!$1:$218,A7+2,FALSE) -> 10.488088
A8: 8 | B8: 132 | C8: 132 | D8: 132 | E8: RAL 9022 | F8: Pearl light grey | G8: =HLOOKUP(E8,'TTD-DOS'!$1:$218,A8+2,FALSE) -> 1.7320508
A9: 9 | B9: 148 | C9: 148 | D9: 148 | E9: RAL 7036 | F9: Platinum grey | G9: =HLOOKUP(E9,'TTD-DOS'!$1:$218,A9+2,FALSE) -> 3.7416574
A10: 10 | B10: 168 | C10: 168 | D10: 168 | E10: RAL 7038 | F10: Agate grey | G10: =HLOOKUP(E10,'TTD-DOS'!$1:$218,A10+2,FALSE) -> 11.445523
A11: 11 | B11: 184 | C11: 184 | D11: 184 | E11: RAL 7044 | F11: Silk grey | G11: =HLOOKUP(E11,'TTD-DOS'!$1:$218,A11+2,FALSE) -> 16.881943
A12: 12 | B12: 200 | C12: 200 | D12: 200 | E12: RAL 7047 | F12: Telegrey 4 | G12: =HLOOKUP(E12,'TTD-DOS'!$1:$218,A12+2,FALSE) -> 1
... A196: 214 | B196: 88 | C196: 152 | D196: 172 | E196: RAL 5014 | F196: Pigeon blue | G196: =HLOOKUP(E196,'TTD-DOS'!$1:$218,A196+2,FALSE) -> 39.038443

Sheet Pl
A1: 1 | B1: 203 | C1: 2.8284271 | D1: RAL 9005 | E1: Jet black
A2: 2 | B2: 84 | C2: 10.198039 | D2: RAL 5004 | E2: Black blue
A3: 3 | B3: 156 | C3: 4.472136 | D3: RAL 7021 | E3: Black grey
A4: 4 | B4: 160 | C4: 9.8994949 | D4: RAL 7026 | E4: Granite grey
A5: 5 | B5: 173 | C5: 2.236068 | D5: RAL 7043 | E5: Traffic grey B
A6: 6 | B6: 170 | C6: 8.7177979 | D6: RAL 7039 | E6: Quartz grey
A7: 7 | B7: 212 | C7: 10.488088 | D7: RAL 9023 | E7: Pearl dark grey
A8: 8 | B8: 211 | C8: 1.7320508 | D8: RAL 9022 | E8: Pearl light grey
A9: 9 | B9: 167 | C9: 3.7416574 | D9: RAL 7036 | E9: Platinum grey
A10: 10 | B10: 169 | C10: 11.445523 | D10: RAL 7038 | E10: Agate grey
A11: 11 | B11: 174 | C11: 16.881943 | D11: RAL 7044 | E11: Silk grey
A12: 12 | B12: 177 | C12: 1 | D12: RAL 7047 | E12: Telegrey 4
... A214: 214 | B214: 102 | C214: 16.155494 | D214: RAL 5024 | E214: Pastel blue

Sheet PL_Design
A1: 1 | B1: 721 | C1: 44.777226 | D1: H140L20C05 | E1: Melanite Black Green
A2: 2 | B2: 0 | C2: 2.4494897 | D2: H000L15C00 | E2: Ink Black
A3: 3 | B3: 804 | C3: 6.164414 | D3: H160L20C05 | E3: Beryl Black Green
A4: 4 | B4: 3 | C4: 6.4031242 | D4: H000L30C00 | E4: Medium Black
A5: 5 | B5: 4 | C5: 0 | D5: H000L35C00 | E5: Briquette Grey
A6: 6 | B6: 1596 | C6: 8.3066239 | D6: H320L40C05 | E6: Slate Mauve
A7: 7 | B7: 7 | C7: 3 | D7: H000L50C00 | E7: Steel Grey
A8: 8 | B8: 8 | C8: 3.4641016 | D8: H000L55C00 | E8: Medium Grey
A9: 9 | B9: 1612 | C9: 6.3245553 | D9: H320L60C05 | E9: Aragonite Grey
A10: 10 | B10: 750 | C10: 6.4031242 | D10: H140L70C05 | E10: Ginkgo Green
A11: 11 | B11: 12 | C11: 3.4641016 | D11: H000L75C00 | E11: Marble Grey
A12: 12 | B12: 13 | C12: 1.4142136 | D12: H000L80C00 | E12: Foggy Grey
... A214: 214 | B214: 1165 | C214: 8.0622577 | D214: H220L60C20 | E214: Frost Blue

Sheet xUSSR
A1: 1 | B1: RAL 8022 | C1: Black brown | D1: =HLOOKUP(B1,'TTD-DOS'!$1:$218,ROW()+2,FALSE) -> 15.165751
A2: 2 | B2: RAL 9004 | C2: Signal black | D2: =HLOOKUP(B2,'TTD-DOS'!$1:$218,ROW()+2,FALSE) -> 19.646883
A3: 3 | B3: RAL 6014 | C3: Yellow olive | D3: =HLOOKUP(B3,'TTD-DOS'!$1:$218,ROW()+2,FALSE) -> 28.248894
A4: 4 | B4: RAL 7022 | C4: Umbra grey | D4: =HLOOKUP(B4,'TTD-DOS'!$1:$218,ROW()+2,FALSE) -> 16.124515
A5: 5 | B5: RAL 7009 | C5: Green grey | D5: =HLOOKUP(B5,'TTD-DOS'!$1:$218,ROW()+2,FALSE) -> 21.540659
A6: 6 | B6: RAL 7005 | C6: Mouse grey | D6: =HLOOKUP(B6,'TTD-DOS'!$1:$218,ROW()+2,FALSE) -> 14.071247
A7: 7 | B7: RAL 7023 | C7: Concrete grey | D7: =HLOOKUP(B7,'TTD-DOS'!$1:$218,ROW()+2,FALSE) -> 16.401219
A8: 8 | B8: RAL 7037 | C8: Dusty grey | D8: =HLOOKUP(B8,'TTD-DOS'!$1:$218,ROW()+2,FALSE) -> 16.763055
A9: 9 | B9: RAL 7042 | C9: Traffic grey A | D9: =HLOOKUP(B9,'TTD-DOS'!$1:$218,ROW()+2,FALSE) -> 7
A10: 10 | B10: RAL 9006 | C10: White aluminium | D10: =HLOOKUP(B10,'TTD-DOS'!$1:$218,ROW()+2,FALSE) -> 12.727922
A11: 11 | B11: RAL 7038 | C11: Agate grey | D11: =HLOOKUP(B11,'TTD-DOS'!$1:$218,ROW()+2,FALSE) -> 18.841444
A12: 12 | B12: RAL 7044 | C12: Silk grey | D12: =HLOOKUP(B12,'TTD-DOS'!$1:$218,ROW()+2,FALSE) -> 42.296572
... A214: 214 | B214: RAL 5024 | C214: Pastel blue | D214: =HLOOKUP(B214,'TTD-DOS'!$1:$218,ROW()+2,FALSE) -> 16.155494

Sheet ResultClassic
A1: ='TTD-DOS'!A1 -> Num | B1: HEX | C1: ='TTD-DOS'!B1 -> R | D1: ='TTD-DOS'!C1 -> G | E1: ='TTD-DOS'!D1 -> B | F1: Colour | G1: EXCEL | H1: =AVERAGE(H2:H300) -> 27.173233 | I1: Colour | J1: ChatGPT | K1: =AVERAGE(K2:K300) -> 27.495889 | L1: Colour | M1: Pl Script | N1: =AVERAGE(N2:N300) -> 51.962242 | O1: Colour | P1: Back | Q1: =AVERAGE(Q2:Q300) -> 19.316936 | R1: Colour | S1: xUSSRset | T1: =AVERAGE(T2:T300) -> 35.433082 | U1: Min | V1: Colour | W1: Result | X1: =AVERAGE(X2:X300) -> 34.213858
A2: ='TTD-DOS'!A2 -> 0 | B2: =DEC2HEX(A2,2) -> 00 | C2: ='TTD-DOS'!B2 -> 0 | D2: ='TTD-DOS'!C2 -> 0 | E2: ='TTD-DOS'!D2 -> 255 | I2: =IFERROR(VLOOKUP(ROW()-2,ChatGPT!$A:$F,5,FALSE),"") | J2: =IFERROR(VLOOKUP(ROW()-2,ChatGPT!$A:$F,6,FALSE),"") | K2: =IFERROR(VLOOKUP(ROW()-2,ChatGPT!$A:$G,7,FALSE),"") | L2: =IFERROR(VLOOKUP(ROW()-2,Pl!$A:$F,4,FALSE),"") | M2: =IFERROR(VLOOKUP(ROW()-2,Pl!$A:$F,5,FALSE),"") | N2: =IFERROR(VLOOKUP(ROW()-2,Pl!$A:$F,3,FALSE),"") | O2: =IFERROR(VLOOKUP(A2,'Ral Classic'!$F:$K,COLUMN('Ral Classic'!$K$1)-COLUMN('Ral Classic'!$F$1)+1,FALSE),"") | P2: =IFERROR(VLOOKUP(O2,'Ral Classic'!$A:$O,COLUMN('Ral Classic'!$L$1),FALSE),"") | Q2: =IFERROR(HLOOKUP(O2,'TTD-DOS'!$1:$218,ROW(),FALSE),"") | W2: =IFERROR(VLOOKUP(V2,'Ral Classic'!$A:$O,COLUMN('Ral Classic'!$L$1),FALSE),"")
A3: ='TTD-DOS'!A3 -> 1 | B3: =DEC2HEX(A3,2) -> 01 | C3: ='TTD-DOS'!B3 -> 16 | D3: ='TTD-DOS'!C3 -> 16 | E3: ='TTD-DOS'!D3 -> 16 | F3: ='TTD-DOS'!F3 -> RAL 9005 | G3: ='TTD-DOS'!G3 -> Jet black | H3: ='TTD-DOS'!E3 -> 2.8284271 | I3: =IFERROR(VLOOKUP(ROW()-2,ChatGPT!$A:$F,5,FALSE),"") -> RAL 9005 | J3: =IFERROR(VLOOKUP(ROW()-2,ChatGPT!$A:$F,6,FALSE),"") -> Jet black | K3: =IFERROR(VLOOKUP(ROW()-2,ChatGPT!$A:$G,7,FALSE),"") -> 2.8284271 | L3: =IFERROR(VLOOKUP(ROW()-2,Pl!$A:$F,4,FALSE),"") -> RAL 9005 | M3: =IFERROR(VLOOKUP(ROW()-2,Pl!$A:$F,5,FALSE),"") -> Jet black | N3: =IFERROR(VLOOKUP(ROW()-2,Pl!$A:$F,3,FALSE),"") -> 2.8284271 | O3: =IFERROR(VLOOKUP(A3,'Ral Classic'!$F:$K,COLUMN('Ral Classic'!$K$1)-COLUMN('Ral Classic'!$F$1)+1,FALSE),"") -> RAL 9005 | P3: =IFERROR(VLOOKUP(O3,'Ral Classic'!$A:$O,COLUMN('Ral Classic'!$L$1),FALSE),"") -> Jet black | Q3: =IFERROR(HLOOKUP(O3,'TTD-DOS'!$1:$218,ROW(),FALSE),"") -> 2.8284271 | R3: =xUSSR!B1 -> RAL 8022 | S3: =xUSSR!C1 -> Black brown | T3: =xUSSR!D1 -> 15.165751 | U3: =MIN(F3:T3) -> 2.8284271 | V3: RAL 9005 | W3: =IFERROR(VLOOKUP(V3,'Ral Classic'!$A:$O,COLUMN('Ral Classic'!$L$1),FALSE),"") -> Jet black | X3: =HLOOKUP(V3,'TTD-DOS'!$1:$218,ROW(),FALSE) -> 2.8284271
A4: ='TTD-DOS'!A4 -> 2 | B4: =DEC2HEX(A4,2) -> 02 | C4: ='TTD-DOS'!B4 -> 32 | D4: ='TTD-DOS'!C4 -> 32 | E4: ='TTD-DOS'!D4 -> 32 | F4: ='TTD-DOS'!F4 -> RAL 5004 | G4: ='TTD-DOS'!G4 -> Black blue | H4: ='TTD-DOS'!E4 -> 10.198039 | I4: =IFERROR(VLOOKUP(ROW()-2,ChatGPT!$A:$F,5,FALSE),"") -> RAL 5004 | J4: =IFERROR(VLOOKUP(ROW()-2,ChatGPT!$A:$F,6,FALSE),"") -> Black blue | K4: =IFERROR(VLOOKUP(ROW()-2,ChatGPT!$A:$G,7,FALSE),"") -> 10.198039 | L4: =IFERROR(VLOOKUP(ROW()-2,Pl!$A:$F,4,FALSE),"") -> RAL 5004 | M4: =IFERROR(VLOOKUP(ROW()-2,Pl!$A:$F,5,FALSE),"") -> Black blue | N4: =IFERROR(VLOOKUP(ROW()-2,Pl!$A:$F,3,FALSE),"") -> 10.198039 | O4: =IFERROR(VLOOKUP(A4,'Ral Classic'!$F:$K,COLUMN('Ral Classic'!$K$1)-COLUMN('Ral Classic'!$F$1)+1,FALSE),"") -> RAL 5004 | P4: =IFERROR(VLOOKUP(O4,'Ral Classic'!$A:$O,COLUMN('Ral Classic'!$L$1),FALSE),"") -> Black blue | Q4: =IFERROR(HLOOKUP(O4,'TTD-DOS'!$1:$218,ROW(),FALSE),"") -> 10.198039 | R4: =xUSSR!B2 -> RAL 9004 | S4: =xUSSR!C2 -> Signal black | T4: =xUSSR!D2 -> 19.646883 | U4: =MIN(F4:T4) -> 10.198039 | V4: RAL 5004 | W4: =IFERROR(VLOOKUP(V4,'Ral Classic'!$A:$O,COLUMN('Ral Classic'!$L$1),FALSE),"") -> Black blue | X4: =HLOOKUP(V4,'TTD-DOS'!$1:$218,ROW(),FALSE) -> 10.198039
A5: ='TTD-DOS'!A5 -> 3 | B5: =DEC2HEX(A5,2) -> 03 | C5: ='TTD-DOS'!B5 -> 48 | D5: ='TTD-DOS'!C5 -> 48 | E5: ='TTD-DOS'!D5 -> 48 | F5: ='TTD-DOS'!F5 -> RAL 7021 | G5: ='TTD-DOS'!G5 -> Black grey | H5: ='TTD-DOS'!E5 -> 4.472136 | I5: =IFERROR(VLOOKUP(ROW()-2,ChatGPT!$A:$F,5,FALSE),"") -> RAL 7021 | J5: =IFERROR(VLOOKUP(ROW()-2,ChatGPT!$A:$F,6,FALSE),"") -> Black grey | K5: =IFERROR(VLOOKUP(ROW()-2,ChatGPT!$A:$G,7,FALSE),"") -> 4.472136 | L5: =IFERROR(VLOOKUP(ROW()-2,Pl!$A:$F,4,FALSE),"") -> RAL 7021 | M5: =IFERROR(VLOOKUP(ROW()-2,Pl!$A:$F,5,FALSE),"") -> Black grey | N5: =IFERROR(VLOOKUP(ROW()-2,Pl!$A:$F,3,FALSE),"") -> 4.472136 | O5: =IFERROR(VLOOKUP(A5,'Ral Classic'!$F:$K,COLUMN('Ral Classic'!$K$1)-COLUMN('Ral Classic'!$F$1)+1,FALSE),"") -> RAL 4007 | P5: =IFERROR(VLOOKUP(O5,'Ral Classic'!$A:$O,COLUMN('Ral Classic'!$L$1),FALSE),"") -> Purple violet | Q5: =IFERROR(HLOOKUP(O5,'TTD-DOS'!$1:$218,ROW(),FALSE),"") -> 28.583212 | R5: =xUSSR!B3 -> RAL 6014 | S5: =xUSSR!C3 -> Yellow olive | T5: =xUSSR!D3 -> 28.248894 | U5: =MIN(F5:T5) -> 4.472136 | V5: RAL 7021 | W5: =IFERROR(VLOOKUP(V5,'Ral Classic'!$A:$O,COLUMN('Ral Classic'!$L$1),FALSE),"") -> Black grey | X5: =HLOOKUP(V5,'TTD-DOS'!$1:$218,ROW(),FALSE) -> 4.472136
A6: ='TTD-DOS'!A6 -> 4 | B6: =DEC2HEX(A6,2) -> 04 | C6: ='TTD-DOS'!B6 -> 64 | D6: ='TTD-DOS'!C6 -> 64 | E6: ='TTD-DOS'!D6 -> 64 | F6: ='TTD-DOS'!F6 -> RAL 7016 | G6: ='TTD-DOS'!G6 -> Anthracite grey | H6: ='TTD-DOS'!E6 -> 8.4852814 | I6: =IFERROR(VLOOKUP(ROW()-2,ChatGPT!$A:$F,5,FALSE),"") -> RAL 7016 | J6: =IFERROR(VLOOKUP(ROW()-2,ChatGPT!$A:$F,6,FALSE),"") -> Anthracite grey | K6: =IFERROR(VLOOKUP(ROW()-2,ChatGPT!$A:$G,7,FALSE),"") -> 8.4852814 | L6: =IFERROR(VLOOKUP(ROW()-2,Pl!$A:$F,4,FALSE),"") -> RAL 7026 | M6: =IFERROR(VLOOKUP(ROW()-2,Pl!$A:$F,5,FALSE),"") -> Granite grey | N6: =IFERROR(VLOOKUP(ROW()-2,Pl!$A:$F,3,FALSE),"") -> 9.8994949 | O6: =IFERROR(VLOOKUP(A6,'Ral Classic'!$F:$K,COLUMN('Ral Classic'!$K$1)-COLUMN('Ral Classic'!$F$1)+1,FALSE),"") -> RAL 6014 | P6: =IFERROR(VLOOKUP(O6,'Ral Classic'!$A:$O,COLUMN('Ral Classic'!$L$1),FALSE),"") -> Yellow olive | Q6: =IFERROR(HLOOKUP(O6,'TTD-DOS'!$1:$218,ROW(),FALSE),"") -> 12.569805 | R6: =xUSSR!B4 -> RAL 7022 | S6: =xUSSR!C4 -> Umbra grey | T6: =xUSSR!D4 -> 16.124515 | U6: =MIN(F6:T6) -> 8.4852814 | V6: RAL 7026 | W6: =IFERROR(VLOOKUP(V6,'Ral Classic'!$A:$O,COLUMN('Ral Classic'!$L$1),FALSE),"") -> Granite grey | X6: =HLOOKUP(V6,'TTD-DOS'!$1:$218,ROW(),FALSE) -> 9.8994949
A7: ='TTD-DOS'!A7 -> 5 | B7: =DEC2HEX(A7,2) -> 05 | C7: ='TTD-DOS'!B7 -> 80 | D7: ='TTD-DOS'!C7 -> 80 | E7: ='TTD-DOS'!D7 -> 80 | F7: ='TTD-DOS'!F7 -> RAL 7043 | G7: ='TTD-DOS'!G7 -> Traffic grey B | H7: ='TTD-DOS'!E7 -> 2.236068 | I7: =IFERROR(VLOOKUP(ROW()-2,ChatGPT!$A:$F,5,FALSE),"") -> RAL 7043 | J7: =IFERROR(VLOOKUP(ROW()-2,ChatGPT!$A:$F,6,FALSE),"") -> Traffic grey B | K7: =IFERROR(VLOOKUP(ROW()-2,ChatGPT!$A:$G,7,FALSE),"") -> 2.236068 | L7: =IFERROR(VLOOKUP(ROW()-2,Pl!$A:$F,4,FALSE),"") -> RAL 7043 | M7: =IFERROR(VLOOKUP(ROW()-2,Pl!$A:$F,5,FALSE),"") -> Traffic grey B | N7: =IFERROR(VLOOKUP(ROW()-2,Pl!$A:$F,3,FALSE),"") -> 2.236068 | O7: =IFERROR(VLOOKUP(A7,'Ral Classic'!$F:$K,COLUMN('Ral Classic'!$K$1)-COLUMN('Ral Classic'!$F$1)+1,FALSE),"") -> RAL 7010 | P7: =IFERROR(VLOOKUP(O7,'Ral Classic'!$A:$O,COLUMN('Ral Classic'!$L$1),FALSE),"") -> Tarpaulin grey | Q7: =IFERROR(HLOOKUP(O7,'TTD-DOS'!$1:$218,ROW(),FALSE),"") -> 15.620499 | R7: =xUSSR!B5 -> RAL 7009 | S7: =xUSSR!C5 -> Green grey | T7: =xUSSR!D5 -> 21.540659 | U7: =MIN(F7:T7) -> 2.236068 | V7: RAL 7043 | W7: =IFERROR(VLOOKUP(V7,'Ral Classic'!$A:$O,COLUMN('Ral Classic'!$L$1),FALSE),"") -> Traffic grey B | X7: =HLOOKUP(V7,'TTD-DOS'!$1:$218,ROW(),FALSE) -> 2.236068
A8: ='TTD-DOS'!A8 -> 6 | B8: =DEC2HEX(A8,2) -> 06 | C8: ='TTD-DOS'!B8 -> 100 | D8: ='TTD-DOS'!C8 -> 100 | E8: ='TTD-DOS'!D8 -> 100 | F8: ='TTD-DOS'!F8 -> RAL 7039 | G8: ='TTD-DOS'!G8 -> Quartz grey | H8: ='TTD-DOS'!E8 -> 8.7177979 | I8: =IFERROR(VLOOKUP(ROW()-2,ChatGPT!$A:$F,5,FALSE),"") -> RAL 7039 | J8: =IFERROR(VLOOKUP(ROW()-2,ChatGPT!$A:$F,6,FALSE),"") -> Quartz grey | K8: =IFERROR(VLOOKUP(ROW()-2,ChatGPT!$A:$G,7,FALSE),"") -> 8.7177979 | L8: =IFERROR(VLOOKUP(ROW()-2,Pl!$A:$F,4,FALSE),"") -> RAL 7039 | M8: =IFERROR(VLOOKUP(ROW()-2,Pl!$A:$F,5,FALSE),"") -> Quartz grey | N8: =IFERROR(VLOOKUP(ROW()-2,Pl!$A:$F,3,FALSE),"") -> 8.7177979 | O8: =IFERROR(VLOOKUP(A8,'Ral Classic'!$F:$K,COLUMN('Ral Classic'!$K$1)-COLUMN('Ral Classic'!$F$1)+1,FALSE),"") -> RAL 7005 | P8: =IFERROR(VLOOKUP(O8,'Ral Classic'!$A:$O,COLUMN('Ral Classic'!$L$1),FALSE),"") -> Mouse grey | Q8: =IFERROR(HLOOKUP(O8,'TTD-DOS'!$1:$218,ROW(),FALSE),"") -> 14.071247 | R8: =xUSSR!B6 -> RAL 7005 | S8: =xUSSR!C6 -> Mouse grey | T8: =xUSSR!D6 -> 14.071247 | U8: =MIN(F8:T8) -> 8.7177979 | V8: RAL 7039 | W8: =IFERROR(VLOOKUP(V8,'Ral Classic'!$A:$O,COLUMN('Ral Classic'!$L$1),FALSE),"") -> Quartz grey | X8: =HLOOKUP(V8,'TTD-DOS'!$1:$218,ROW(),FALSE) -> 8.7177979
